[2022-12-17T04:16:18.055+0000] {processor.py:153} INFO - Started process (PID=33) to work on /opt/airflow/dags/scheduler.py
[2022-12-17T04:16:18.057+0000] {processor.py:743} INFO - Processing file /opt/airflow/dags/scheduler.py for tasks to queue
[2022-12-17T04:16:18.058+0000] {logging_mixin.py:137} INFO - [2022-12-17T04:16:18.058+0000] {dagbag.py:538} INFO - Filling up the DagBag from /opt/airflow/dags/scheduler.py
[2022-12-17T04:16:18.096+0000] {logging_mixin.py:137} INFO - [2022-12-17T04:16:18.094+0000] {dagbag.py:343} ERROR - Failed to import: /opt/airflow/dags/scheduler.py
Traceback (most recent call last):
  File "/home/airflow/.local/lib/python3.7/site-packages/airflow/models/dagbag.py", line 339, in parse
    loader.exec_module(new_module)
  File "<frozen importlib._bootstrap_external>", line 728, in exec_module
  File "<frozen importlib._bootstrap>", line 219, in _call_with_frames_removed
  File "/opt/airflow/dags/scheduler.py", line 7, in <module>
    import mysql.connector
ModuleNotFoundError: No module named 'mysql'
[2022-12-17T04:16:18.097+0000] {processor.py:755} WARNING - No viable dags retrieved from /opt/airflow/dags/scheduler.py
[2022-12-17T04:16:18.116+0000] {processor.py:175} INFO - Processing /opt/airflow/dags/scheduler.py took 0.065 seconds
[2022-12-17T04:16:48.591+0000] {processor.py:153} INFO - Started process (PID=108) to work on /opt/airflow/dags/scheduler.py
[2022-12-17T04:16:48.593+0000] {processor.py:743} INFO - Processing file /opt/airflow/dags/scheduler.py for tasks to queue
[2022-12-17T04:16:48.594+0000] {logging_mixin.py:137} INFO - [2022-12-17T04:16:48.594+0000] {dagbag.py:538} INFO - Filling up the DagBag from /opt/airflow/dags/scheduler.py
[2022-12-17T04:16:48.603+0000] {logging_mixin.py:137} INFO - [2022-12-17T04:16:48.602+0000] {dagbag.py:343} ERROR - Failed to import: /opt/airflow/dags/scheduler.py
Traceback (most recent call last):
  File "/home/airflow/.local/lib/python3.7/site-packages/airflow/models/dagbag.py", line 339, in parse
    loader.exec_module(new_module)
  File "<frozen importlib._bootstrap_external>", line 728, in exec_module
  File "<frozen importlib._bootstrap>", line 219, in _call_with_frames_removed
  File "/opt/airflow/dags/scheduler.py", line 7, in <module>
    import mysql.connector
ModuleNotFoundError: No module named 'mysql'
[2022-12-17T04:16:48.604+0000] {processor.py:755} WARNING - No viable dags retrieved from /opt/airflow/dags/scheduler.py
[2022-12-17T04:16:48.641+0000] {processor.py:175} INFO - Processing /opt/airflow/dags/scheduler.py took 0.054 seconds
[2022-12-17T04:17:18.985+0000] {processor.py:153} INFO - Started process (PID=171) to work on /opt/airflow/dags/scheduler.py
[2022-12-17T04:17:18.986+0000] {processor.py:743} INFO - Processing file /opt/airflow/dags/scheduler.py for tasks to queue
[2022-12-17T04:17:18.987+0000] {logging_mixin.py:137} INFO - [2022-12-17T04:17:18.987+0000] {dagbag.py:538} INFO - Filling up the DagBag from /opt/airflow/dags/scheduler.py
[2022-12-17T04:17:18.997+0000] {logging_mixin.py:137} INFO - [2022-12-17T04:17:18.996+0000] {dagbag.py:343} ERROR - Failed to import: /opt/airflow/dags/scheduler.py
Traceback (most recent call last):
  File "/home/airflow/.local/lib/python3.7/site-packages/airflow/models/dagbag.py", line 339, in parse
    loader.exec_module(new_module)
  File "<frozen importlib._bootstrap_external>", line 728, in exec_module
  File "<frozen importlib._bootstrap>", line 219, in _call_with_frames_removed
  File "/opt/airflow/dags/scheduler.py", line 7, in <module>
    import mysql.connector
ModuleNotFoundError: No module named 'mysql'
[2022-12-17T04:17:18.998+0000] {processor.py:755} WARNING - No viable dags retrieved from /opt/airflow/dags/scheduler.py
[2022-12-17T04:17:19.015+0000] {processor.py:175} INFO - Processing /opt/airflow/dags/scheduler.py took 0.033 seconds
[2022-12-17T04:17:49.612+0000] {processor.py:153} INFO - Started process (PID=245) to work on /opt/airflow/dags/scheduler.py
[2022-12-17T04:17:49.613+0000] {processor.py:743} INFO - Processing file /opt/airflow/dags/scheduler.py for tasks to queue
[2022-12-17T04:17:49.616+0000] {logging_mixin.py:137} INFO - [2022-12-17T04:17:49.616+0000] {dagbag.py:538} INFO - Filling up the DagBag from /opt/airflow/dags/scheduler.py
[2022-12-17T04:17:49.630+0000] {logging_mixin.py:137} INFO - [2022-12-17T04:17:49.627+0000] {dagbag.py:343} ERROR - Failed to import: /opt/airflow/dags/scheduler.py
Traceback (most recent call last):
  File "/home/airflow/.local/lib/python3.7/site-packages/airflow/models/dagbag.py", line 339, in parse
    loader.exec_module(new_module)
  File "<frozen importlib._bootstrap_external>", line 728, in exec_module
  File "<frozen importlib._bootstrap>", line 219, in _call_with_frames_removed
  File "/opt/airflow/dags/scheduler.py", line 7, in <module>
    import mysql.connector
ModuleNotFoundError: No module named 'mysql'
[2022-12-17T04:17:49.631+0000] {processor.py:755} WARNING - No viable dags retrieved from /opt/airflow/dags/scheduler.py
[2022-12-17T04:17:49.654+0000] {processor.py:175} INFO - Processing /opt/airflow/dags/scheduler.py took 0.048 seconds
[2022-12-17T04:18:19.898+0000] {processor.py:153} INFO - Started process (PID=319) to work on /opt/airflow/dags/scheduler.py
[2022-12-17T04:18:19.901+0000] {processor.py:743} INFO - Processing file /opt/airflow/dags/scheduler.py for tasks to queue
[2022-12-17T04:18:19.903+0000] {logging_mixin.py:137} INFO - [2022-12-17T04:18:19.903+0000] {dagbag.py:538} INFO - Filling up the DagBag from /opt/airflow/dags/scheduler.py
[2022-12-17T04:18:19.918+0000] {logging_mixin.py:137} INFO - [2022-12-17T04:18:19.916+0000] {dagbag.py:343} ERROR - Failed to import: /opt/airflow/dags/scheduler.py
Traceback (most recent call last):
  File "/home/airflow/.local/lib/python3.7/site-packages/airflow/models/dagbag.py", line 339, in parse
    loader.exec_module(new_module)
  File "<frozen importlib._bootstrap_external>", line 728, in exec_module
  File "<frozen importlib._bootstrap>", line 219, in _call_with_frames_removed
  File "/opt/airflow/dags/scheduler.py", line 7, in <module>
    import mysql.connector
ModuleNotFoundError: No module named 'mysql'
[2022-12-17T04:18:19.918+0000] {processor.py:755} WARNING - No viable dags retrieved from /opt/airflow/dags/scheduler.py
[2022-12-17T04:18:19.940+0000] {processor.py:175} INFO - Processing /opt/airflow/dags/scheduler.py took 0.049 seconds
[2022-12-17T04:18:50.202+0000] {processor.py:153} INFO - Started process (PID=391) to work on /opt/airflow/dags/scheduler.py
[2022-12-17T04:18:50.204+0000] {processor.py:743} INFO - Processing file /opt/airflow/dags/scheduler.py for tasks to queue
[2022-12-17T04:18:50.205+0000] {logging_mixin.py:137} INFO - [2022-12-17T04:18:50.205+0000] {dagbag.py:538} INFO - Filling up the DagBag from /opt/airflow/dags/scheduler.py
[2022-12-17T04:18:50.215+0000] {logging_mixin.py:137} INFO - [2022-12-17T04:18:50.214+0000] {dagbag.py:343} ERROR - Failed to import: /opt/airflow/dags/scheduler.py
Traceback (most recent call last):
  File "/home/airflow/.local/lib/python3.7/site-packages/airflow/models/dagbag.py", line 339, in parse
    loader.exec_module(new_module)
  File "<frozen importlib._bootstrap_external>", line 728, in exec_module
  File "<frozen importlib._bootstrap>", line 219, in _call_with_frames_removed
  File "/opt/airflow/dags/scheduler.py", line 7, in <module>
    import mysql.connector
ModuleNotFoundError: No module named 'mysql'
[2022-12-17T04:18:50.216+0000] {processor.py:755} WARNING - No viable dags retrieved from /opt/airflow/dags/scheduler.py
[2022-12-17T04:18:50.233+0000] {processor.py:175} INFO - Processing /opt/airflow/dags/scheduler.py took 0.035 seconds
[2022-12-17T04:19:20.861+0000] {processor.py:153} INFO - Started process (PID=457) to work on /opt/airflow/dags/scheduler.py
[2022-12-17T04:19:20.864+0000] {processor.py:743} INFO - Processing file /opt/airflow/dags/scheduler.py for tasks to queue
[2022-12-17T04:19:20.865+0000] {logging_mixin.py:137} INFO - [2022-12-17T04:19:20.865+0000] {dagbag.py:538} INFO - Filling up the DagBag from /opt/airflow/dags/scheduler.py
[2022-12-17T04:19:20.879+0000] {logging_mixin.py:137} INFO - [2022-12-17T04:19:20.877+0000] {dagbag.py:343} ERROR - Failed to import: /opt/airflow/dags/scheduler.py
Traceback (most recent call last):
  File "/home/airflow/.local/lib/python3.7/site-packages/airflow/models/dagbag.py", line 339, in parse
    loader.exec_module(new_module)
  File "<frozen importlib._bootstrap_external>", line 728, in exec_module
  File "<frozen importlib._bootstrap>", line 219, in _call_with_frames_removed
  File "/opt/airflow/dags/scheduler.py", line 7, in <module>
    import mysql.connector
ModuleNotFoundError: No module named 'mysql'
[2022-12-17T04:19:20.880+0000] {processor.py:755} WARNING - No viable dags retrieved from /opt/airflow/dags/scheduler.py
[2022-12-17T04:19:20.902+0000] {processor.py:175} INFO - Processing /opt/airflow/dags/scheduler.py took 0.046 seconds
[2022-12-17T04:19:51.074+0000] {processor.py:153} INFO - Started process (PID=532) to work on /opt/airflow/dags/scheduler.py
[2022-12-17T04:19:51.075+0000] {processor.py:743} INFO - Processing file /opt/airflow/dags/scheduler.py for tasks to queue
[2022-12-17T04:19:51.076+0000] {logging_mixin.py:137} INFO - [2022-12-17T04:19:51.076+0000] {dagbag.py:538} INFO - Filling up the DagBag from /opt/airflow/dags/scheduler.py
[2022-12-17T04:19:51.084+0000] {logging_mixin.py:137} INFO - [2022-12-17T04:19:51.083+0000] {dagbag.py:343} ERROR - Failed to import: /opt/airflow/dags/scheduler.py
Traceback (most recent call last):
  File "/home/airflow/.local/lib/python3.7/site-packages/airflow/models/dagbag.py", line 339, in parse
    loader.exec_module(new_module)
  File "<frozen importlib._bootstrap_external>", line 728, in exec_module
  File "<frozen importlib._bootstrap>", line 219, in _call_with_frames_removed
  File "/opt/airflow/dags/scheduler.py", line 7, in <module>
    import mysql.connector
ModuleNotFoundError: No module named 'mysql'
[2022-12-17T04:19:51.085+0000] {processor.py:755} WARNING - No viable dags retrieved from /opt/airflow/dags/scheduler.py
[2022-12-17T04:19:51.102+0000] {processor.py:175} INFO - Processing /opt/airflow/dags/scheduler.py took 0.032 seconds
[2022-12-17T04:20:21.484+0000] {processor.py:153} INFO - Started process (PID=608) to work on /opt/airflow/dags/scheduler.py
[2022-12-17T04:20:21.485+0000] {processor.py:743} INFO - Processing file /opt/airflow/dags/scheduler.py for tasks to queue
[2022-12-17T04:20:21.486+0000] {logging_mixin.py:137} INFO - [2022-12-17T04:20:21.486+0000] {dagbag.py:538} INFO - Filling up the DagBag from /opt/airflow/dags/scheduler.py
[2022-12-17T04:20:21.496+0000] {logging_mixin.py:137} INFO - [2022-12-17T04:20:21.494+0000] {dagbag.py:343} ERROR - Failed to import: /opt/airflow/dags/scheduler.py
Traceback (most recent call last):
  File "/home/airflow/.local/lib/python3.7/site-packages/airflow/models/dagbag.py", line 339, in parse
    loader.exec_module(new_module)
  File "<frozen importlib._bootstrap_external>", line 728, in exec_module
  File "<frozen importlib._bootstrap>", line 219, in _call_with_frames_removed
  File "/opt/airflow/dags/scheduler.py", line 7, in <module>
    import mysql.connector
ModuleNotFoundError: No module named 'mysql'
[2022-12-17T04:20:21.497+0000] {processor.py:755} WARNING - No viable dags retrieved from /opt/airflow/dags/scheduler.py
[2022-12-17T04:20:21.515+0000] {processor.py:175} INFO - Processing /opt/airflow/dags/scheduler.py took 0.034 seconds
[2022-12-17T04:20:51.772+0000] {processor.py:153} INFO - Started process (PID=672) to work on /opt/airflow/dags/scheduler.py
[2022-12-17T04:20:51.773+0000] {processor.py:743} INFO - Processing file /opt/airflow/dags/scheduler.py for tasks to queue
[2022-12-17T04:20:51.774+0000] {logging_mixin.py:137} INFO - [2022-12-17T04:20:51.774+0000] {dagbag.py:538} INFO - Filling up the DagBag from /opt/airflow/dags/scheduler.py
[2022-12-17T04:20:51.783+0000] {logging_mixin.py:137} INFO - [2022-12-17T04:20:51.781+0000] {dagbag.py:343} ERROR - Failed to import: /opt/airflow/dags/scheduler.py
Traceback (most recent call last):
  File "/home/airflow/.local/lib/python3.7/site-packages/airflow/models/dagbag.py", line 339, in parse
    loader.exec_module(new_module)
  File "<frozen importlib._bootstrap_external>", line 728, in exec_module
  File "<frozen importlib._bootstrap>", line 219, in _call_with_frames_removed
  File "/opt/airflow/dags/scheduler.py", line 7, in <module>
    import mysql.connector
ModuleNotFoundError: No module named 'mysql'
[2022-12-17T04:20:51.784+0000] {processor.py:755} WARNING - No viable dags retrieved from /opt/airflow/dags/scheduler.py
[2022-12-17T04:20:51.802+0000] {processor.py:175} INFO - Processing /opt/airflow/dags/scheduler.py took 0.034 seconds
[2022-12-17T04:21:22.247+0000] {processor.py:153} INFO - Started process (PID=747) to work on /opt/airflow/dags/scheduler.py
[2022-12-17T04:21:22.250+0000] {processor.py:743} INFO - Processing file /opt/airflow/dags/scheduler.py for tasks to queue
[2022-12-17T04:21:22.251+0000] {logging_mixin.py:137} INFO - [2022-12-17T04:21:22.251+0000] {dagbag.py:538} INFO - Filling up the DagBag from /opt/airflow/dags/scheduler.py
[2022-12-17T04:21:22.262+0000] {logging_mixin.py:137} INFO - [2022-12-17T04:21:22.260+0000] {dagbag.py:343} ERROR - Failed to import: /opt/airflow/dags/scheduler.py
Traceback (most recent call last):
  File "/home/airflow/.local/lib/python3.7/site-packages/airflow/models/dagbag.py", line 339, in parse
    loader.exec_module(new_module)
  File "<frozen importlib._bootstrap_external>", line 728, in exec_module
  File "<frozen importlib._bootstrap>", line 219, in _call_with_frames_removed
  File "/opt/airflow/dags/scheduler.py", line 7, in <module>
    import mysql.connector
ModuleNotFoundError: No module named 'mysql'
[2022-12-17T04:21:22.262+0000] {processor.py:755} WARNING - No viable dags retrieved from /opt/airflow/dags/scheduler.py
[2022-12-17T04:21:22.283+0000] {processor.py:175} INFO - Processing /opt/airflow/dags/scheduler.py took 0.041 seconds
[2022-12-17T04:22:25.780+0000] {processor.py:153} INFO - Started process (PID=33) to work on /opt/airflow/dags/scheduler.py
[2022-12-17T04:22:25.782+0000] {processor.py:743} INFO - Processing file /opt/airflow/dags/scheduler.py for tasks to queue
[2022-12-17T04:22:25.784+0000] {logging_mixin.py:137} INFO - [2022-12-17T04:22:25.784+0000] {dagbag.py:538} INFO - Filling up the DagBag from /opt/airflow/dags/scheduler.py
[2022-12-17T04:22:25.808+0000] {logging_mixin.py:137} INFO - [2022-12-17T04:22:25.806+0000] {dagbag.py:343} ERROR - Failed to import: /opt/airflow/dags/scheduler.py
Traceback (most recent call last):
  File "/home/airflow/.local/lib/python3.7/site-packages/airflow/models/dagbag.py", line 339, in parse
    loader.exec_module(new_module)
  File "<frozen importlib._bootstrap_external>", line 728, in exec_module
  File "<frozen importlib._bootstrap>", line 219, in _call_with_frames_removed
  File "/opt/airflow/dags/scheduler.py", line 7, in <module>
    import mysql.connector
ModuleNotFoundError: No module named 'mysql'
[2022-12-17T04:22:25.809+0000] {processor.py:755} WARNING - No viable dags retrieved from /opt/airflow/dags/scheduler.py
[2022-12-17T04:22:25.827+0000] {processor.py:175} INFO - Processing /opt/airflow/dags/scheduler.py took 0.049 seconds
[2022-12-17T04:22:56.021+0000] {processor.py:153} INFO - Started process (PID=71) to work on /opt/airflow/dags/scheduler.py
[2022-12-17T04:22:56.023+0000] {processor.py:743} INFO - Processing file /opt/airflow/dags/scheduler.py for tasks to queue
[2022-12-17T04:22:56.024+0000] {logging_mixin.py:137} INFO - [2022-12-17T04:22:56.024+0000] {dagbag.py:538} INFO - Filling up the DagBag from /opt/airflow/dags/scheduler.py
[2022-12-17T04:22:56.037+0000] {logging_mixin.py:137} INFO - [2022-12-17T04:22:56.036+0000] {dagbag.py:343} ERROR - Failed to import: /opt/airflow/dags/scheduler.py
Traceback (most recent call last):
  File "/home/airflow/.local/lib/python3.7/site-packages/airflow/models/dagbag.py", line 339, in parse
    loader.exec_module(new_module)
  File "<frozen importlib._bootstrap_external>", line 728, in exec_module
  File "<frozen importlib._bootstrap>", line 219, in _call_with_frames_removed
  File "/opt/airflow/dags/scheduler.py", line 7, in <module>
    import mysql.connector
ModuleNotFoundError: No module named 'mysql'
[2022-12-17T04:22:56.039+0000] {processor.py:755} WARNING - No viable dags retrieved from /opt/airflow/dags/scheduler.py
[2022-12-17T04:22:56.058+0000] {processor.py:175} INFO - Processing /opt/airflow/dags/scheduler.py took 0.042 seconds
[2022-12-17T04:23:26.361+0000] {processor.py:153} INFO - Started process (PID=95) to work on /opt/airflow/dags/scheduler.py
[2022-12-17T04:23:26.363+0000] {processor.py:743} INFO - Processing file /opt/airflow/dags/scheduler.py for tasks to queue
[2022-12-17T04:23:26.365+0000] {logging_mixin.py:137} INFO - [2022-12-17T04:23:26.365+0000] {dagbag.py:538} INFO - Filling up the DagBag from /opt/airflow/dags/scheduler.py
[2022-12-17T04:23:26.378+0000] {logging_mixin.py:137} INFO - [2022-12-17T04:23:26.375+0000] {dagbag.py:343} ERROR - Failed to import: /opt/airflow/dags/scheduler.py
Traceback (most recent call last):
  File "/home/airflow/.local/lib/python3.7/site-packages/airflow/models/dagbag.py", line 339, in parse
    loader.exec_module(new_module)
  File "<frozen importlib._bootstrap_external>", line 728, in exec_module
  File "<frozen importlib._bootstrap>", line 219, in _call_with_frames_removed
  File "/opt/airflow/dags/scheduler.py", line 7, in <module>
    import mysql.connector
ModuleNotFoundError: No module named 'mysql'
[2022-12-17T04:23:26.379+0000] {processor.py:755} WARNING - No viable dags retrieved from /opt/airflow/dags/scheduler.py
[2022-12-17T04:23:26.400+0000] {processor.py:175} INFO - Processing /opt/airflow/dags/scheduler.py took 0.042 seconds
[2022-12-17T04:23:56.653+0000] {processor.py:153} INFO - Started process (PID=132) to work on /opt/airflow/dags/scheduler.py
[2022-12-17T04:23:56.655+0000] {processor.py:743} INFO - Processing file /opt/airflow/dags/scheduler.py for tasks to queue
[2022-12-17T04:23:56.656+0000] {logging_mixin.py:137} INFO - [2022-12-17T04:23:56.656+0000] {dagbag.py:538} INFO - Filling up the DagBag from /opt/airflow/dags/scheduler.py
[2022-12-17T04:23:56.676+0000] {logging_mixin.py:137} INFO - [2022-12-17T04:23:56.674+0000] {dagbag.py:343} ERROR - Failed to import: /opt/airflow/dags/scheduler.py
Traceback (most recent call last):
  File "/home/airflow/.local/lib/python3.7/site-packages/airflow/models/dagbag.py", line 339, in parse
    loader.exec_module(new_module)
  File "<frozen importlib._bootstrap_external>", line 728, in exec_module
  File "<frozen importlib._bootstrap>", line 219, in _call_with_frames_removed
  File "/opt/airflow/dags/scheduler.py", line 7, in <module>
    import mysql.connector
ModuleNotFoundError: No module named 'mysql'
[2022-12-17T04:23:56.677+0000] {processor.py:755} WARNING - No viable dags retrieved from /opt/airflow/dags/scheduler.py
[2022-12-17T04:23:56.698+0000] {processor.py:175} INFO - Processing /opt/airflow/dags/scheduler.py took 0.051 seconds
[2022-12-17T04:24:26.921+0000] {processor.py:153} INFO - Started process (PID=168) to work on /opt/airflow/dags/scheduler.py
[2022-12-17T04:24:26.923+0000] {processor.py:743} INFO - Processing file /opt/airflow/dags/scheduler.py for tasks to queue
[2022-12-17T04:24:26.924+0000] {logging_mixin.py:137} INFO - [2022-12-17T04:24:26.924+0000] {dagbag.py:538} INFO - Filling up the DagBag from /opt/airflow/dags/scheduler.py
[2022-12-17T04:24:26.936+0000] {logging_mixin.py:137} INFO - [2022-12-17T04:24:26.934+0000] {dagbag.py:343} ERROR - Failed to import: /opt/airflow/dags/scheduler.py
Traceback (most recent call last):
  File "/home/airflow/.local/lib/python3.7/site-packages/airflow/models/dagbag.py", line 339, in parse
    loader.exec_module(new_module)
  File "<frozen importlib._bootstrap_external>", line 728, in exec_module
  File "<frozen importlib._bootstrap>", line 219, in _call_with_frames_removed
  File "/opt/airflow/dags/scheduler.py", line 7, in <module>
    import mysql.connector
ModuleNotFoundError: No module named 'mysql'
[2022-12-17T04:24:26.937+0000] {processor.py:755} WARNING - No viable dags retrieved from /opt/airflow/dags/scheduler.py
[2022-12-17T04:24:26.957+0000] {processor.py:175} INFO - Processing /opt/airflow/dags/scheduler.py took 0.039 seconds
[2022-12-17T04:24:57.185+0000] {processor.py:153} INFO - Started process (PID=192) to work on /opt/airflow/dags/scheduler.py
[2022-12-17T04:24:57.187+0000] {processor.py:743} INFO - Processing file /opt/airflow/dags/scheduler.py for tasks to queue
[2022-12-17T04:24:57.189+0000] {logging_mixin.py:137} INFO - [2022-12-17T04:24:57.189+0000] {dagbag.py:538} INFO - Filling up the DagBag from /opt/airflow/dags/scheduler.py
[2022-12-17T04:24:57.203+0000] {logging_mixin.py:137} INFO - [2022-12-17T04:24:57.201+0000] {dagbag.py:343} ERROR - Failed to import: /opt/airflow/dags/scheduler.py
Traceback (most recent call last):
  File "/home/airflow/.local/lib/python3.7/site-packages/airflow/models/dagbag.py", line 339, in parse
    loader.exec_module(new_module)
  File "<frozen importlib._bootstrap_external>", line 728, in exec_module
  File "<frozen importlib._bootstrap>", line 219, in _call_with_frames_removed
  File "/opt/airflow/dags/scheduler.py", line 7, in <module>
    import mysql.connector
ModuleNotFoundError: No module named 'mysql'
[2022-12-17T04:24:57.205+0000] {processor.py:755} WARNING - No viable dags retrieved from /opt/airflow/dags/scheduler.py
[2022-12-17T04:24:57.228+0000] {processor.py:175} INFO - Processing /opt/airflow/dags/scheduler.py took 0.048 seconds
[2022-12-17T04:25:27.456+0000] {processor.py:153} INFO - Started process (PID=228) to work on /opt/airflow/dags/scheduler.py
[2022-12-17T04:25:27.458+0000] {processor.py:743} INFO - Processing file /opt/airflow/dags/scheduler.py for tasks to queue
[2022-12-17T04:25:27.460+0000] {logging_mixin.py:137} INFO - [2022-12-17T04:25:27.460+0000] {dagbag.py:538} INFO - Filling up the DagBag from /opt/airflow/dags/scheduler.py
[2022-12-17T04:25:27.476+0000] {logging_mixin.py:137} INFO - [2022-12-17T04:25:27.474+0000] {dagbag.py:343} ERROR - Failed to import: /opt/airflow/dags/scheduler.py
Traceback (most recent call last):
  File "/home/airflow/.local/lib/python3.7/site-packages/airflow/models/dagbag.py", line 339, in parse
    loader.exec_module(new_module)
  File "<frozen importlib._bootstrap_external>", line 728, in exec_module
  File "<frozen importlib._bootstrap>", line 219, in _call_with_frames_removed
  File "/opt/airflow/dags/scheduler.py", line 7, in <module>
    import mysql.connector
ModuleNotFoundError: No module named 'mysql'
[2022-12-17T04:25:27.478+0000] {processor.py:755} WARNING - No viable dags retrieved from /opt/airflow/dags/scheduler.py
[2022-12-17T04:25:27.499+0000] {processor.py:175} INFO - Processing /opt/airflow/dags/scheduler.py took 0.049 seconds
[2022-12-17T04:25:57.699+0000] {processor.py:153} INFO - Started process (PID=265) to work on /opt/airflow/dags/scheduler.py
[2022-12-17T04:25:57.703+0000] {processor.py:743} INFO - Processing file /opt/airflow/dags/scheduler.py for tasks to queue
[2022-12-17T04:25:57.705+0000] {logging_mixin.py:137} INFO - [2022-12-17T04:25:57.705+0000] {dagbag.py:538} INFO - Filling up the DagBag from /opt/airflow/dags/scheduler.py
[2022-12-17T04:25:57.721+0000] {logging_mixin.py:137} INFO - [2022-12-17T04:25:57.719+0000] {dagbag.py:343} ERROR - Failed to import: /opt/airflow/dags/scheduler.py
Traceback (most recent call last):
  File "/home/airflow/.local/lib/python3.7/site-packages/airflow/models/dagbag.py", line 339, in parse
    loader.exec_module(new_module)
  File "<frozen importlib._bootstrap_external>", line 728, in exec_module
  File "<frozen importlib._bootstrap>", line 219, in _call_with_frames_removed
  File "/opt/airflow/dags/scheduler.py", line 7, in <module>
    import mysql.connector
ModuleNotFoundError: No module named 'mysql'
[2022-12-17T04:25:57.722+0000] {processor.py:755} WARNING - No viable dags retrieved from /opt/airflow/dags/scheduler.py
[2022-12-17T04:25:57.742+0000] {processor.py:175} INFO - Processing /opt/airflow/dags/scheduler.py took 0.049 seconds
[2022-12-17T04:26:28.027+0000] {processor.py:153} INFO - Started process (PID=291) to work on /opt/airflow/dags/scheduler.py
[2022-12-17T04:26:28.029+0000] {processor.py:743} INFO - Processing file /opt/airflow/dags/scheduler.py for tasks to queue
[2022-12-17T04:26:28.032+0000] {logging_mixin.py:137} INFO - [2022-12-17T04:26:28.032+0000] {dagbag.py:538} INFO - Filling up the DagBag from /opt/airflow/dags/scheduler.py
[2022-12-17T04:26:28.046+0000] {logging_mixin.py:137} INFO - [2022-12-17T04:26:28.044+0000] {dagbag.py:343} ERROR - Failed to import: /opt/airflow/dags/scheduler.py
Traceback (most recent call last):
  File "/home/airflow/.local/lib/python3.7/site-packages/airflow/models/dagbag.py", line 339, in parse
    loader.exec_module(new_module)
  File "<frozen importlib._bootstrap_external>", line 728, in exec_module
  File "<frozen importlib._bootstrap>", line 219, in _call_with_frames_removed
  File "/opt/airflow/dags/scheduler.py", line 7, in <module>
    import mysql.connector
ModuleNotFoundError: No module named 'mysql'
[2022-12-17T04:26:28.047+0000] {processor.py:755} WARNING - No viable dags retrieved from /opt/airflow/dags/scheduler.py
[2022-12-17T04:26:28.066+0000] {processor.py:175} INFO - Processing /opt/airflow/dags/scheduler.py took 0.044 seconds
[2022-12-17T04:26:58.288+0000] {processor.py:153} INFO - Started process (PID=328) to work on /opt/airflow/dags/scheduler.py
[2022-12-17T04:26:58.289+0000] {processor.py:743} INFO - Processing file /opt/airflow/dags/scheduler.py for tasks to queue
[2022-12-17T04:26:58.290+0000] {logging_mixin.py:137} INFO - [2022-12-17T04:26:58.290+0000] {dagbag.py:538} INFO - Filling up the DagBag from /opt/airflow/dags/scheduler.py
[2022-12-17T04:26:58.297+0000] {logging_mixin.py:137} INFO - [2022-12-17T04:26:58.296+0000] {dagbag.py:343} ERROR - Failed to import: /opt/airflow/dags/scheduler.py
Traceback (most recent call last):
  File "/home/airflow/.local/lib/python3.7/site-packages/airflow/models/dagbag.py", line 339, in parse
    loader.exec_module(new_module)
  File "<frozen importlib._bootstrap_external>", line 728, in exec_module
  File "<frozen importlib._bootstrap>", line 219, in _call_with_frames_removed
  File "/opt/airflow/dags/scheduler.py", line 7, in <module>
    import mysql.connector
ModuleNotFoundError: No module named 'mysql'
[2022-12-17T04:26:58.298+0000] {processor.py:755} WARNING - No viable dags retrieved from /opt/airflow/dags/scheduler.py
[2022-12-17T04:26:58.314+0000] {processor.py:175} INFO - Processing /opt/airflow/dags/scheduler.py took 0.029 seconds
[2022-12-17T04:27:28.513+0000] {processor.py:153} INFO - Started process (PID=366) to work on /opt/airflow/dags/scheduler.py
[2022-12-17T04:27:28.515+0000] {processor.py:743} INFO - Processing file /opt/airflow/dags/scheduler.py for tasks to queue
[2022-12-17T04:27:28.516+0000] {logging_mixin.py:137} INFO - [2022-12-17T04:27:28.516+0000] {dagbag.py:538} INFO - Filling up the DagBag from /opt/airflow/dags/scheduler.py
[2022-12-17T04:27:28.525+0000] {logging_mixin.py:137} INFO - [2022-12-17T04:27:28.524+0000] {dagbag.py:343} ERROR - Failed to import: /opt/airflow/dags/scheduler.py
Traceback (most recent call last):
  File "/home/airflow/.local/lib/python3.7/site-packages/airflow/models/dagbag.py", line 339, in parse
    loader.exec_module(new_module)
  File "<frozen importlib._bootstrap_external>", line 728, in exec_module
  File "<frozen importlib._bootstrap>", line 219, in _call_with_frames_removed
  File "/opt/airflow/dags/scheduler.py", line 7, in <module>
    import mysql.connector
ModuleNotFoundError: No module named 'mysql'
[2022-12-17T04:27:28.526+0000] {processor.py:755} WARNING - No viable dags retrieved from /opt/airflow/dags/scheduler.py
[2022-12-17T04:27:28.542+0000] {processor.py:175} INFO - Processing /opt/airflow/dags/scheduler.py took 0.032 seconds
[2022-12-17T04:27:58.755+0000] {processor.py:153} INFO - Started process (PID=391) to work on /opt/airflow/dags/scheduler.py
[2022-12-17T04:27:58.756+0000] {processor.py:743} INFO - Processing file /opt/airflow/dags/scheduler.py for tasks to queue
[2022-12-17T04:27:58.758+0000] {logging_mixin.py:137} INFO - [2022-12-17T04:27:58.758+0000] {dagbag.py:538} INFO - Filling up the DagBag from /opt/airflow/dags/scheduler.py
[2022-12-17T04:27:58.767+0000] {logging_mixin.py:137} INFO - [2022-12-17T04:27:58.766+0000] {dagbag.py:343} ERROR - Failed to import: /opt/airflow/dags/scheduler.py
Traceback (most recent call last):
  File "/home/airflow/.local/lib/python3.7/site-packages/airflow/models/dagbag.py", line 339, in parse
    loader.exec_module(new_module)
  File "<frozen importlib._bootstrap_external>", line 728, in exec_module
  File "<frozen importlib._bootstrap>", line 219, in _call_with_frames_removed
  File "/opt/airflow/dags/scheduler.py", line 7, in <module>
    import mysql.connector
ModuleNotFoundError: No module named 'mysql'
[2022-12-17T04:27:58.768+0000] {processor.py:755} WARNING - No viable dags retrieved from /opt/airflow/dags/scheduler.py
[2022-12-17T04:27:58.784+0000] {processor.py:175} INFO - Processing /opt/airflow/dags/scheduler.py took 0.033 seconds
[2022-12-17T04:29:13.791+0000] {processor.py:153} INFO - Started process (PID=33) to work on /opt/airflow/dags/scheduler.py
[2022-12-17T04:29:13.793+0000] {processor.py:743} INFO - Processing file /opt/airflow/dags/scheduler.py for tasks to queue
[2022-12-17T04:29:13.794+0000] {logging_mixin.py:137} INFO - [2022-12-17T04:29:13.794+0000] {dagbag.py:538} INFO - Filling up the DagBag from /opt/airflow/dags/scheduler.py
[2022-12-17T04:29:13.809+0000] {logging_mixin.py:137} INFO - [2022-12-17T04:29:13.807+0000] {dagbag.py:343} ERROR - Failed to import: /opt/airflow/dags/scheduler.py
Traceback (most recent call last):
  File "/home/airflow/.local/lib/python3.7/site-packages/airflow/models/dagbag.py", line 339, in parse
    loader.exec_module(new_module)
  File "<frozen importlib._bootstrap_external>", line 728, in exec_module
  File "<frozen importlib._bootstrap>", line 219, in _call_with_frames_removed
  File "/opt/airflow/dags/scheduler.py", line 7, in <module>
    import mysql.connector
ModuleNotFoundError: No module named 'mysql'
[2022-12-17T04:29:13.811+0000] {processor.py:755} WARNING - No viable dags retrieved from /opt/airflow/dags/scheduler.py
[2022-12-17T04:29:13.836+0000] {processor.py:175} INFO - Processing /opt/airflow/dags/scheduler.py took 0.049 seconds
[2022-12-17T04:29:44.043+0000] {processor.py:153} INFO - Started process (PID=70) to work on /opt/airflow/dags/scheduler.py
[2022-12-17T04:29:44.045+0000] {processor.py:743} INFO - Processing file /opt/airflow/dags/scheduler.py for tasks to queue
[2022-12-17T04:29:44.047+0000] {logging_mixin.py:137} INFO - [2022-12-17T04:29:44.047+0000] {dagbag.py:538} INFO - Filling up the DagBag from /opt/airflow/dags/scheduler.py
[2022-12-17T04:29:44.060+0000] {logging_mixin.py:137} INFO - [2022-12-17T04:29:44.058+0000] {dagbag.py:343} ERROR - Failed to import: /opt/airflow/dags/scheduler.py
Traceback (most recent call last):
  File "/home/airflow/.local/lib/python3.7/site-packages/airflow/models/dagbag.py", line 339, in parse
    loader.exec_module(new_module)
  File "<frozen importlib._bootstrap_external>", line 728, in exec_module
  File "<frozen importlib._bootstrap>", line 219, in _call_with_frames_removed
  File "/opt/airflow/dags/scheduler.py", line 7, in <module>
    import mysql.connector
ModuleNotFoundError: No module named 'mysql'
[2022-12-17T04:29:44.060+0000] {processor.py:755} WARNING - No viable dags retrieved from /opt/airflow/dags/scheduler.py
[2022-12-17T04:29:44.080+0000] {processor.py:175} INFO - Processing /opt/airflow/dags/scheduler.py took 0.043 seconds
[2022-12-17T04:30:14.314+0000] {processor.py:153} INFO - Started process (PID=94) to work on /opt/airflow/dags/scheduler.py
[2022-12-17T04:30:14.316+0000] {processor.py:743} INFO - Processing file /opt/airflow/dags/scheduler.py for tasks to queue
[2022-12-17T04:30:14.317+0000] {logging_mixin.py:137} INFO - [2022-12-17T04:30:14.316+0000] {dagbag.py:538} INFO - Filling up the DagBag from /opt/airflow/dags/scheduler.py
[2022-12-17T04:30:14.326+0000] {logging_mixin.py:137} INFO - [2022-12-17T04:30:14.324+0000] {dagbag.py:343} ERROR - Failed to import: /opt/airflow/dags/scheduler.py
Traceback (most recent call last):
  File "/home/airflow/.local/lib/python3.7/site-packages/airflow/models/dagbag.py", line 339, in parse
    loader.exec_module(new_module)
  File "<frozen importlib._bootstrap_external>", line 728, in exec_module
  File "<frozen importlib._bootstrap>", line 219, in _call_with_frames_removed
  File "/opt/airflow/dags/scheduler.py", line 7, in <module>
    import mysql.connector
ModuleNotFoundError: No module named 'mysql'
[2022-12-17T04:30:14.328+0000] {processor.py:755} WARNING - No viable dags retrieved from /opt/airflow/dags/scheduler.py
[2022-12-17T04:30:14.348+0000] {processor.py:175} INFO - Processing /opt/airflow/dags/scheduler.py took 0.036 seconds
[2022-12-17T04:30:44.580+0000] {processor.py:153} INFO - Started process (PID=132) to work on /opt/airflow/dags/scheduler.py
[2022-12-17T04:30:44.582+0000] {processor.py:743} INFO - Processing file /opt/airflow/dags/scheduler.py for tasks to queue
[2022-12-17T04:30:44.584+0000] {logging_mixin.py:137} INFO - [2022-12-17T04:30:44.584+0000] {dagbag.py:538} INFO - Filling up the DagBag from /opt/airflow/dags/scheduler.py
[2022-12-17T04:30:44.601+0000] {logging_mixin.py:137} INFO - [2022-12-17T04:30:44.600+0000] {dagbag.py:343} ERROR - Failed to import: /opt/airflow/dags/scheduler.py
Traceback (most recent call last):
  File "/home/airflow/.local/lib/python3.7/site-packages/airflow/models/dagbag.py", line 339, in parse
    loader.exec_module(new_module)
  File "<frozen importlib._bootstrap_external>", line 728, in exec_module
  File "<frozen importlib._bootstrap>", line 219, in _call_with_frames_removed
  File "/opt/airflow/dags/scheduler.py", line 7, in <module>
    import mysql.connector
ModuleNotFoundError: No module named 'mysql'
[2022-12-17T04:30:44.602+0000] {processor.py:755} WARNING - No viable dags retrieved from /opt/airflow/dags/scheduler.py
[2022-12-17T04:30:44.624+0000] {processor.py:175} INFO - Processing /opt/airflow/dags/scheduler.py took 0.049 seconds
[2022-12-17T04:31:14.800+0000] {processor.py:153} INFO - Started process (PID=168) to work on /opt/airflow/dags/scheduler.py
[2022-12-17T04:31:14.802+0000] {processor.py:743} INFO - Processing file /opt/airflow/dags/scheduler.py for tasks to queue
[2022-12-17T04:31:14.804+0000] {logging_mixin.py:137} INFO - [2022-12-17T04:31:14.804+0000] {dagbag.py:538} INFO - Filling up the DagBag from /opt/airflow/dags/scheduler.py
[2022-12-17T04:31:14.818+0000] {logging_mixin.py:137} INFO - [2022-12-17T04:31:14.816+0000] {dagbag.py:343} ERROR - Failed to import: /opt/airflow/dags/scheduler.py
Traceback (most recent call last):
  File "/home/airflow/.local/lib/python3.7/site-packages/airflow/models/dagbag.py", line 339, in parse
    loader.exec_module(new_module)
  File "<frozen importlib._bootstrap_external>", line 728, in exec_module
  File "<frozen importlib._bootstrap>", line 219, in _call_with_frames_removed
  File "/opt/airflow/dags/scheduler.py", line 7, in <module>
    import mysql.connector
ModuleNotFoundError: No module named 'mysql'
[2022-12-17T04:31:14.819+0000] {processor.py:755} WARNING - No viable dags retrieved from /opt/airflow/dags/scheduler.py
[2022-12-17T04:31:14.840+0000] {processor.py:175} INFO - Processing /opt/airflow/dags/scheduler.py took 0.044 seconds
[2022-12-17T04:31:45.100+0000] {processor.py:153} INFO - Started process (PID=193) to work on /opt/airflow/dags/scheduler.py
[2022-12-17T04:31:45.103+0000] {processor.py:743} INFO - Processing file /opt/airflow/dags/scheduler.py for tasks to queue
[2022-12-17T04:31:45.104+0000] {logging_mixin.py:137} INFO - [2022-12-17T04:31:45.104+0000] {dagbag.py:538} INFO - Filling up the DagBag from /opt/airflow/dags/scheduler.py
[2022-12-17T04:31:45.118+0000] {logging_mixin.py:137} INFO - [2022-12-17T04:31:45.116+0000] {dagbag.py:343} ERROR - Failed to import: /opt/airflow/dags/scheduler.py
Traceback (most recent call last):
  File "/home/airflow/.local/lib/python3.7/site-packages/airflow/models/dagbag.py", line 339, in parse
    loader.exec_module(new_module)
  File "<frozen importlib._bootstrap_external>", line 728, in exec_module
  File "<frozen importlib._bootstrap>", line 219, in _call_with_frames_removed
  File "/opt/airflow/dags/scheduler.py", line 7, in <module>
    import mysql.connector
ModuleNotFoundError: No module named 'mysql'
[2022-12-17T04:31:45.119+0000] {processor.py:755} WARNING - No viable dags retrieved from /opt/airflow/dags/scheduler.py
[2022-12-17T04:31:45.142+0000] {processor.py:175} INFO - Processing /opt/airflow/dags/scheduler.py took 0.048 seconds
[2022-12-17T04:32:15.359+0000] {processor.py:153} INFO - Started process (PID=229) to work on /opt/airflow/dags/scheduler.py
[2022-12-17T04:32:15.361+0000] {processor.py:743} INFO - Processing file /opt/airflow/dags/scheduler.py for tasks to queue
[2022-12-17T04:32:15.363+0000] {logging_mixin.py:137} INFO - [2022-12-17T04:32:15.363+0000] {dagbag.py:538} INFO - Filling up the DagBag from /opt/airflow/dags/scheduler.py
[2022-12-17T04:32:15.375+0000] {logging_mixin.py:137} INFO - [2022-12-17T04:32:15.373+0000] {dagbag.py:343} ERROR - Failed to import: /opt/airflow/dags/scheduler.py
Traceback (most recent call last):
  File "/home/airflow/.local/lib/python3.7/site-packages/airflow/models/dagbag.py", line 339, in parse
    loader.exec_module(new_module)
  File "<frozen importlib._bootstrap_external>", line 728, in exec_module
  File "<frozen importlib._bootstrap>", line 219, in _call_with_frames_removed
  File "/opt/airflow/dags/scheduler.py", line 7, in <module>
    import mysql.connector
ModuleNotFoundError: No module named 'mysql'
[2022-12-17T04:32:15.376+0000] {processor.py:755} WARNING - No viable dags retrieved from /opt/airflow/dags/scheduler.py
[2022-12-17T04:32:15.397+0000] {processor.py:175} INFO - Processing /opt/airflow/dags/scheduler.py took 0.043 seconds
[2022-12-17T04:32:45.628+0000] {processor.py:153} INFO - Started process (PID=265) to work on /opt/airflow/dags/scheduler.py
[2022-12-17T04:32:45.630+0000] {processor.py:743} INFO - Processing file /opt/airflow/dags/scheduler.py for tasks to queue
[2022-12-17T04:32:45.632+0000] {logging_mixin.py:137} INFO - [2022-12-17T04:32:45.632+0000] {dagbag.py:538} INFO - Filling up the DagBag from /opt/airflow/dags/scheduler.py
[2022-12-17T04:32:45.645+0000] {logging_mixin.py:137} INFO - [2022-12-17T04:32:45.643+0000] {dagbag.py:343} ERROR - Failed to import: /opt/airflow/dags/scheduler.py
Traceback (most recent call last):
  File "/home/airflow/.local/lib/python3.7/site-packages/airflow/models/dagbag.py", line 339, in parse
    loader.exec_module(new_module)
  File "<frozen importlib._bootstrap_external>", line 728, in exec_module
  File "<frozen importlib._bootstrap>", line 219, in _call_with_frames_removed
  File "/opt/airflow/dags/scheduler.py", line 7, in <module>
    import mysql.connector
ModuleNotFoundError: No module named 'mysql'
[2022-12-17T04:32:45.646+0000] {processor.py:755} WARNING - No viable dags retrieved from /opt/airflow/dags/scheduler.py
[2022-12-17T04:32:45.669+0000] {processor.py:175} INFO - Processing /opt/airflow/dags/scheduler.py took 0.046 seconds
[2022-12-17T04:33:15.889+0000] {processor.py:153} INFO - Started process (PID=291) to work on /opt/airflow/dags/scheduler.py
[2022-12-17T04:33:15.891+0000] {processor.py:743} INFO - Processing file /opt/airflow/dags/scheduler.py for tasks to queue
[2022-12-17T04:33:15.892+0000] {logging_mixin.py:137} INFO - [2022-12-17T04:33:15.892+0000] {dagbag.py:538} INFO - Filling up the DagBag from /opt/airflow/dags/scheduler.py
[2022-12-17T04:33:15.903+0000] {logging_mixin.py:137} INFO - [2022-12-17T04:33:15.901+0000] {dagbag.py:343} ERROR - Failed to import: /opt/airflow/dags/scheduler.py
Traceback (most recent call last):
  File "/home/airflow/.local/lib/python3.7/site-packages/airflow/models/dagbag.py", line 339, in parse
    loader.exec_module(new_module)
  File "<frozen importlib._bootstrap_external>", line 728, in exec_module
  File "<frozen importlib._bootstrap>", line 219, in _call_with_frames_removed
  File "/opt/airflow/dags/scheduler.py", line 7, in <module>
    import mysql.connector
ModuleNotFoundError: No module named 'mysql'
[2022-12-17T04:33:15.903+0000] {processor.py:755} WARNING - No viable dags retrieved from /opt/airflow/dags/scheduler.py
[2022-12-17T04:33:15.922+0000] {processor.py:175} INFO - Processing /opt/airflow/dags/scheduler.py took 0.036 seconds
[2022-12-17T04:33:46.117+0000] {processor.py:153} INFO - Started process (PID=328) to work on /opt/airflow/dags/scheduler.py
[2022-12-17T04:33:46.119+0000] {processor.py:743} INFO - Processing file /opt/airflow/dags/scheduler.py for tasks to queue
[2022-12-17T04:33:46.120+0000] {logging_mixin.py:137} INFO - [2022-12-17T04:33:46.119+0000] {dagbag.py:538} INFO - Filling up the DagBag from /opt/airflow/dags/scheduler.py
[2022-12-17T04:33:46.128+0000] {logging_mixin.py:137} INFO - [2022-12-17T04:33:46.127+0000] {dagbag.py:343} ERROR - Failed to import: /opt/airflow/dags/scheduler.py
Traceback (most recent call last):
  File "/home/airflow/.local/lib/python3.7/site-packages/airflow/models/dagbag.py", line 339, in parse
    loader.exec_module(new_module)
  File "<frozen importlib._bootstrap_external>", line 728, in exec_module
  File "<frozen importlib._bootstrap>", line 219, in _call_with_frames_removed
  File "/opt/airflow/dags/scheduler.py", line 7, in <module>
    import mysql.connector
ModuleNotFoundError: No module named 'mysql'
[2022-12-17T04:33:46.129+0000] {processor.py:755} WARNING - No viable dags retrieved from /opt/airflow/dags/scheduler.py
[2022-12-17T04:33:46.146+0000] {processor.py:175} INFO - Processing /opt/airflow/dags/scheduler.py took 0.032 seconds
[2022-12-17T04:34:16.397+0000] {processor.py:153} INFO - Started process (PID=365) to work on /opt/airflow/dags/scheduler.py
[2022-12-17T04:34:16.398+0000] {processor.py:743} INFO - Processing file /opt/airflow/dags/scheduler.py for tasks to queue
[2022-12-17T04:34:16.399+0000] {logging_mixin.py:137} INFO - [2022-12-17T04:34:16.398+0000] {dagbag.py:538} INFO - Filling up the DagBag from /opt/airflow/dags/scheduler.py
[2022-12-17T04:34:16.407+0000] {logging_mixin.py:137} INFO - [2022-12-17T04:34:16.405+0000] {dagbag.py:343} ERROR - Failed to import: /opt/airflow/dags/scheduler.py
Traceback (most recent call last):
  File "/home/airflow/.local/lib/python3.7/site-packages/airflow/models/dagbag.py", line 339, in parse
    loader.exec_module(new_module)
  File "<frozen importlib._bootstrap_external>", line 728, in exec_module
  File "<frozen importlib._bootstrap>", line 219, in _call_with_frames_removed
  File "/opt/airflow/dags/scheduler.py", line 7, in <module>
    import mysql.connector
ModuleNotFoundError: No module named 'mysql'
[2022-12-17T04:34:16.407+0000] {processor.py:755} WARNING - No viable dags retrieved from /opt/airflow/dags/scheduler.py
[2022-12-17T04:34:16.424+0000] {processor.py:175} INFO - Processing /opt/airflow/dags/scheduler.py took 0.029 seconds
[2022-12-17T04:34:46.644+0000] {processor.py:153} INFO - Started process (PID=390) to work on /opt/airflow/dags/scheduler.py
[2022-12-17T04:34:46.645+0000] {processor.py:743} INFO - Processing file /opt/airflow/dags/scheduler.py for tasks to queue
[2022-12-17T04:34:46.646+0000] {logging_mixin.py:137} INFO - [2022-12-17T04:34:46.646+0000] {dagbag.py:538} INFO - Filling up the DagBag from /opt/airflow/dags/scheduler.py
[2022-12-17T04:34:46.655+0000] {logging_mixin.py:137} INFO - [2022-12-17T04:34:46.653+0000] {dagbag.py:343} ERROR - Failed to import: /opt/airflow/dags/scheduler.py
Traceback (most recent call last):
  File "/home/airflow/.local/lib/python3.7/site-packages/airflow/models/dagbag.py", line 339, in parse
    loader.exec_module(new_module)
  File "<frozen importlib._bootstrap_external>", line 728, in exec_module
  File "<frozen importlib._bootstrap>", line 219, in _call_with_frames_removed
  File "/opt/airflow/dags/scheduler.py", line 7, in <module>
    import mysql.connector
ModuleNotFoundError: No module named 'mysql'
[2022-12-17T04:34:46.656+0000] {processor.py:755} WARNING - No viable dags retrieved from /opt/airflow/dags/scheduler.py
[2022-12-17T04:34:46.675+0000] {processor.py:175} INFO - Processing /opt/airflow/dags/scheduler.py took 0.034 seconds
[2022-12-17T04:35:16.918+0000] {processor.py:153} INFO - Started process (PID=427) to work on /opt/airflow/dags/scheduler.py
[2022-12-17T04:35:16.920+0000] {processor.py:743} INFO - Processing file /opt/airflow/dags/scheduler.py for tasks to queue
[2022-12-17T04:35:16.921+0000] {logging_mixin.py:137} INFO - [2022-12-17T04:35:16.921+0000] {dagbag.py:538} INFO - Filling up the DagBag from /opt/airflow/dags/scheduler.py
[2022-12-17T04:35:16.929+0000] {logging_mixin.py:137} INFO - [2022-12-17T04:35:16.927+0000] {dagbag.py:343} ERROR - Failed to import: /opt/airflow/dags/scheduler.py
Traceback (most recent call last):
  File "/home/airflow/.local/lib/python3.7/site-packages/airflow/models/dagbag.py", line 339, in parse
    loader.exec_module(new_module)
  File "<frozen importlib._bootstrap_external>", line 728, in exec_module
  File "<frozen importlib._bootstrap>", line 219, in _call_with_frames_removed
  File "/opt/airflow/dags/scheduler.py", line 7, in <module>
    import mysql.connector
ModuleNotFoundError: No module named 'mysql'
[2022-12-17T04:35:16.929+0000] {processor.py:755} WARNING - No viable dags retrieved from /opt/airflow/dags/scheduler.py
[2022-12-17T04:35:16.947+0000] {processor.py:175} INFO - Processing /opt/airflow/dags/scheduler.py took 0.030 seconds
[2022-12-17T04:35:47.124+0000] {processor.py:153} INFO - Started process (PID=463) to work on /opt/airflow/dags/scheduler.py
[2022-12-17T04:35:47.125+0000] {processor.py:743} INFO - Processing file /opt/airflow/dags/scheduler.py for tasks to queue
[2022-12-17T04:35:47.126+0000] {logging_mixin.py:137} INFO - [2022-12-17T04:35:47.126+0000] {dagbag.py:538} INFO - Filling up the DagBag from /opt/airflow/dags/scheduler.py
[2022-12-17T04:35:47.133+0000] {logging_mixin.py:137} INFO - [2022-12-17T04:35:47.132+0000] {dagbag.py:343} ERROR - Failed to import: /opt/airflow/dags/scheduler.py
Traceback (most recent call last):
  File "/home/airflow/.local/lib/python3.7/site-packages/airflow/models/dagbag.py", line 339, in parse
    loader.exec_module(new_module)
  File "<frozen importlib._bootstrap_external>", line 728, in exec_module
  File "<frozen importlib._bootstrap>", line 219, in _call_with_frames_removed
  File "/opt/airflow/dags/scheduler.py", line 7, in <module>
    import mysql.connector
ModuleNotFoundError: No module named 'mysql'
[2022-12-17T04:35:47.133+0000] {processor.py:755} WARNING - No viable dags retrieved from /opt/airflow/dags/scheduler.py
[2022-12-17T04:35:47.148+0000] {processor.py:175} INFO - Processing /opt/airflow/dags/scheduler.py took 0.026 seconds
[2022-12-17T04:36:17.345+0000] {processor.py:153} INFO - Started process (PID=497) to work on /opt/airflow/dags/scheduler.py
[2022-12-17T04:36:17.346+0000] {processor.py:743} INFO - Processing file /opt/airflow/dags/scheduler.py for tasks to queue
[2022-12-17T04:36:17.347+0000] {logging_mixin.py:137} INFO - [2022-12-17T04:36:17.347+0000] {dagbag.py:538} INFO - Filling up the DagBag from /opt/airflow/dags/scheduler.py
[2022-12-17T04:36:17.354+0000] {logging_mixin.py:137} INFO - [2022-12-17T04:36:17.353+0000] {dagbag.py:343} ERROR - Failed to import: /opt/airflow/dags/scheduler.py
Traceback (most recent call last):
  File "/home/airflow/.local/lib/python3.7/site-packages/airflow/models/dagbag.py", line 339, in parse
    loader.exec_module(new_module)
  File "<frozen importlib._bootstrap_external>", line 728, in exec_module
  File "<frozen importlib._bootstrap>", line 219, in _call_with_frames_removed
  File "/opt/airflow/dags/scheduler.py", line 7, in <module>
    import mysql.connector
ModuleNotFoundError: No module named 'mysql'
[2022-12-17T04:36:17.355+0000] {processor.py:755} WARNING - No viable dags retrieved from /opt/airflow/dags/scheduler.py
[2022-12-17T04:36:17.370+0000] {processor.py:175} INFO - Processing /opt/airflow/dags/scheduler.py took 0.027 seconds
[2022-12-17T04:36:47.602+0000] {processor.py:153} INFO - Started process (PID=525) to work on /opt/airflow/dags/scheduler.py
[2022-12-17T04:36:47.604+0000] {processor.py:743} INFO - Processing file /opt/airflow/dags/scheduler.py for tasks to queue
[2022-12-17T04:36:47.605+0000] {logging_mixin.py:137} INFO - [2022-12-17T04:36:47.605+0000] {dagbag.py:538} INFO - Filling up the DagBag from /opt/airflow/dags/scheduler.py
[2022-12-17T04:36:47.621+0000] {logging_mixin.py:137} INFO - [2022-12-17T04:36:47.619+0000] {dagbag.py:343} ERROR - Failed to import: /opt/airflow/dags/scheduler.py
Traceback (most recent call last):
  File "/home/airflow/.local/lib/python3.7/site-packages/airflow/models/dagbag.py", line 339, in parse
    loader.exec_module(new_module)
  File "<frozen importlib._bootstrap_external>", line 728, in exec_module
  File "<frozen importlib._bootstrap>", line 219, in _call_with_frames_removed
  File "/opt/airflow/dags/scheduler.py", line 7, in <module>
    import mysql.connector
ModuleNotFoundError: No module named 'mysql'
[2022-12-17T04:36:47.622+0000] {processor.py:755} WARNING - No viable dags retrieved from /opt/airflow/dags/scheduler.py
[2022-12-17T04:36:47.647+0000] {processor.py:175} INFO - Processing /opt/airflow/dags/scheduler.py took 0.051 seconds
[2022-12-17T04:37:17.857+0000] {processor.py:153} INFO - Started process (PID=563) to work on /opt/airflow/dags/scheduler.py
[2022-12-17T04:37:17.859+0000] {processor.py:743} INFO - Processing file /opt/airflow/dags/scheduler.py for tasks to queue
[2022-12-17T04:37:17.861+0000] {logging_mixin.py:137} INFO - [2022-12-17T04:37:17.860+0000] {dagbag.py:538} INFO - Filling up the DagBag from /opt/airflow/dags/scheduler.py
[2022-12-17T04:37:17.872+0000] {logging_mixin.py:137} INFO - [2022-12-17T04:37:17.871+0000] {dagbag.py:343} ERROR - Failed to import: /opt/airflow/dags/scheduler.py
Traceback (most recent call last):
  File "/home/airflow/.local/lib/python3.7/site-packages/airflow/models/dagbag.py", line 339, in parse
    loader.exec_module(new_module)
  File "<frozen importlib._bootstrap_external>", line 728, in exec_module
  File "<frozen importlib._bootstrap>", line 219, in _call_with_frames_removed
  File "/opt/airflow/dags/scheduler.py", line 7, in <module>
    import mysql.connector
ModuleNotFoundError: No module named 'mysql'
[2022-12-17T04:37:17.873+0000] {processor.py:755} WARNING - No viable dags retrieved from /opt/airflow/dags/scheduler.py
[2022-12-17T04:37:17.896+0000] {processor.py:175} INFO - Processing /opt/airflow/dags/scheduler.py took 0.042 seconds
[2022-12-17 04:45:04,062] {processor.py:163} INFO - Started process (PID=135) to work on /opt/airflow/dags/scheduler.py
[2022-12-17 04:45:04,074] {processor.py:642} INFO - Processing file /opt/airflow/dags/scheduler.py for tasks to queue
[2022-12-17 04:45:04,076] {logging_mixin.py:109} INFO - [2022-12-17 04:45:04,076] {dagbag.py:500} INFO - Filling up the DagBag from /opt/airflow/dags/scheduler.py
[2022-12-17 04:45:05,657] {logging_mixin.py:109} INFO - [2022-12-17 04:45:05,644] {dagbag.py:334} ERROR - Failed to import: /opt/airflow/dags/scheduler.py
Traceback (most recent call last):
  File "/home/airflow/.local/lib/python3.7/site-packages/mysql/connector/connection_cext.py", line 236, in _open_connection
    self._cmysql.connect(**cnx_kwargs)
_mysql_connector.MySQLInterfaceError: Unknown MySQL server host 'warehouse' (-2)

During handling of the above exception, another exception occurred:

Traceback (most recent call last):
  File "/home/airflow/.local/lib/python3.7/site-packages/airflow/models/dagbag.py", line 331, in _load_modules_from_file
    loader.exec_module(new_module)
  File "<frozen importlib._bootstrap_external>", line 728, in exec_module
  File "<frozen importlib._bootstrap>", line 219, in _call_with_frames_removed
  File "/opt/airflow/dags/scheduler.py", line 17, in <module>
    connection = mysql.connector.connect(user=user, password=password, host=host, port=port, database=database, auth_plugin='mysql_native_password')
  File "/home/airflow/.local/lib/python3.7/site-packages/mysql/connector/__init__.py", line 272, in connect
    return CMySQLConnection(*args, **kwargs)
  File "/home/airflow/.local/lib/python3.7/site-packages/mysql/connector/connection_cext.py", line 85, in __init__
    self.connect(**kwargs)
  File "/home/airflow/.local/lib/python3.7/site-packages/mysql/connector/abstracts.py", line 1014, in connect
    self._open_connection()
  File "/home/airflow/.local/lib/python3.7/site-packages/mysql/connector/connection_cext.py", line 242, in _open_connection
    sqlstate=exc.sqlstate)
mysql.connector.errors.DatabaseError: 2005 (HY000): Unknown MySQL server host 'warehouse' (-2)
[2022-12-17 04:45:05,715] {processor.py:656} WARNING - No viable dags retrieved from /opt/airflow/dags/scheduler.py
[2022-12-17 04:45:05,755] {processor.py:171} INFO - Processing /opt/airflow/dags/scheduler.py took 1.722 seconds
[2022-12-17 04:45:35,949] {processor.py:163} INFO - Started process (PID=169) to work on /opt/airflow/dags/scheduler.py
[2022-12-17 04:45:35,962] {processor.py:642} INFO - Processing file /opt/airflow/dags/scheduler.py for tasks to queue
[2022-12-17 04:45:35,972] {logging_mixin.py:109} INFO - [2022-12-17 04:45:35,972] {dagbag.py:500} INFO - Filling up the DagBag from /opt/airflow/dags/scheduler.py
[2022-12-17 04:45:36,472] {logging_mixin.py:109} INFO - [2022-12-17 04:45:36,451] {dagbag.py:334} ERROR - Failed to import: /opt/airflow/dags/scheduler.py
Traceback (most recent call last):
  File "/home/airflow/.local/lib/python3.7/site-packages/mysql/connector/connection_cext.py", line 236, in _open_connection
    self._cmysql.connect(**cnx_kwargs)
_mysql_connector.MySQLInterfaceError: Unknown MySQL server host 'warehouse' (-2)

During handling of the above exception, another exception occurred:

Traceback (most recent call last):
  File "/home/airflow/.local/lib/python3.7/site-packages/airflow/models/dagbag.py", line 331, in _load_modules_from_file
    loader.exec_module(new_module)
  File "<frozen importlib._bootstrap_external>", line 728, in exec_module
  File "<frozen importlib._bootstrap>", line 219, in _call_with_frames_removed
  File "/opt/airflow/dags/scheduler.py", line 17, in <module>
    connection = mysql.connector.connect(user=user, password=password, host=host, port=port, database=database, auth_plugin='mysql_native_password')
  File "/home/airflow/.local/lib/python3.7/site-packages/mysql/connector/__init__.py", line 272, in connect
    return CMySQLConnection(*args, **kwargs)
  File "/home/airflow/.local/lib/python3.7/site-packages/mysql/connector/connection_cext.py", line 85, in __init__
    self.connect(**kwargs)
  File "/home/airflow/.local/lib/python3.7/site-packages/mysql/connector/abstracts.py", line 1014, in connect
    self._open_connection()
  File "/home/airflow/.local/lib/python3.7/site-packages/mysql/connector/connection_cext.py", line 242, in _open_connection
    sqlstate=exc.sqlstate)
mysql.connector.errors.DatabaseError: 2005 (HY000): Unknown MySQL server host 'warehouse' (-2)
[2022-12-17 04:45:36,610] {processor.py:656} WARNING - No viable dags retrieved from /opt/airflow/dags/scheduler.py
[2022-12-17 04:45:36,725] {processor.py:171} INFO - Processing /opt/airflow/dags/scheduler.py took 0.804 seconds
[2022-12-17 04:46:07,048] {processor.py:163} INFO - Started process (PID=187) to work on /opt/airflow/dags/scheduler.py
[2022-12-17 04:46:07,053] {processor.py:642} INFO - Processing file /opt/airflow/dags/scheduler.py for tasks to queue
[2022-12-17 04:46:07,056] {logging_mixin.py:109} INFO - [2022-12-17 04:46:07,056] {dagbag.py:500} INFO - Filling up the DagBag from /opt/airflow/dags/scheduler.py
[2022-12-17 04:46:07,233] {logging_mixin.py:109} INFO - [2022-12-17 04:46:07,226] {dagbag.py:334} ERROR - Failed to import: /opt/airflow/dags/scheduler.py
Traceback (most recent call last):
  File "/home/airflow/.local/lib/python3.7/site-packages/mysql/connector/connection_cext.py", line 236, in _open_connection
    self._cmysql.connect(**cnx_kwargs)
_mysql_connector.MySQLInterfaceError: Unknown MySQL server host 'warehouse' (-2)

During handling of the above exception, another exception occurred:

Traceback (most recent call last):
  File "/home/airflow/.local/lib/python3.7/site-packages/airflow/models/dagbag.py", line 331, in _load_modules_from_file
    loader.exec_module(new_module)
  File "<frozen importlib._bootstrap_external>", line 728, in exec_module
  File "<frozen importlib._bootstrap>", line 219, in _call_with_frames_removed
  File "/opt/airflow/dags/scheduler.py", line 17, in <module>
    connection = mysql.connector.connect(user=user, password=password, host=host, port=port, database=database, auth_plugin='mysql_native_password')
  File "/home/airflow/.local/lib/python3.7/site-packages/mysql/connector/__init__.py", line 272, in connect
    return CMySQLConnection(*args, **kwargs)
  File "/home/airflow/.local/lib/python3.7/site-packages/mysql/connector/connection_cext.py", line 85, in __init__
    self.connect(**kwargs)
  File "/home/airflow/.local/lib/python3.7/site-packages/mysql/connector/abstracts.py", line 1014, in connect
    self._open_connection()
  File "/home/airflow/.local/lib/python3.7/site-packages/mysql/connector/connection_cext.py", line 242, in _open_connection
    sqlstate=exc.sqlstate)
mysql.connector.errors.DatabaseError: 2005 (HY000): Unknown MySQL server host 'warehouse' (-2)
[2022-12-17 04:46:07,261] {processor.py:656} WARNING - No viable dags retrieved from /opt/airflow/dags/scheduler.py
[2022-12-17 04:46:07,280] {processor.py:171} INFO - Processing /opt/airflow/dags/scheduler.py took 0.243 seconds
[2022-12-17 04:46:37,323] {processor.py:163} INFO - Started process (PID=221) to work on /opt/airflow/dags/scheduler.py
[2022-12-17 04:46:37,327] {processor.py:642} INFO - Processing file /opt/airflow/dags/scheduler.py for tasks to queue
[2022-12-17 04:46:37,329] {logging_mixin.py:109} INFO - [2022-12-17 04:46:37,329] {dagbag.py:500} INFO - Filling up the DagBag from /opt/airflow/dags/scheduler.py
[2022-12-17 04:46:37,558] {logging_mixin.py:109} INFO - [2022-12-17 04:46:37,549] {dagbag.py:334} ERROR - Failed to import: /opt/airflow/dags/scheduler.py
Traceback (most recent call last):
  File "/home/airflow/.local/lib/python3.7/site-packages/mysql/connector/connection_cext.py", line 236, in _open_connection
    self._cmysql.connect(**cnx_kwargs)
_mysql_connector.MySQLInterfaceError: Unknown MySQL server host 'warehouse' (-2)

During handling of the above exception, another exception occurred:

Traceback (most recent call last):
  File "/home/airflow/.local/lib/python3.7/site-packages/airflow/models/dagbag.py", line 331, in _load_modules_from_file
    loader.exec_module(new_module)
  File "<frozen importlib._bootstrap_external>", line 728, in exec_module
  File "<frozen importlib._bootstrap>", line 219, in _call_with_frames_removed
  File "/opt/airflow/dags/scheduler.py", line 17, in <module>
    connection = mysql.connector.connect(user=user, password=password, host=host, port=port, database=database, auth_plugin='mysql_native_password')
  File "/home/airflow/.local/lib/python3.7/site-packages/mysql/connector/__init__.py", line 272, in connect
    return CMySQLConnection(*args, **kwargs)
  File "/home/airflow/.local/lib/python3.7/site-packages/mysql/connector/connection_cext.py", line 85, in __init__
    self.connect(**kwargs)
  File "/home/airflow/.local/lib/python3.7/site-packages/mysql/connector/abstracts.py", line 1014, in connect
    self._open_connection()
  File "/home/airflow/.local/lib/python3.7/site-packages/mysql/connector/connection_cext.py", line 242, in _open_connection
    sqlstate=exc.sqlstate)
mysql.connector.errors.DatabaseError: 2005 (HY000): Unknown MySQL server host 'warehouse' (-2)
[2022-12-17 04:46:37,585] {processor.py:656} WARNING - No viable dags retrieved from /opt/airflow/dags/scheduler.py
[2022-12-17 04:46:37,606] {processor.py:171} INFO - Processing /opt/airflow/dags/scheduler.py took 0.289 seconds
[2022-12-17 04:47:07,785] {processor.py:163} INFO - Started process (PID=239) to work on /opt/airflow/dags/scheduler.py
[2022-12-17 04:47:07,788] {processor.py:642} INFO - Processing file /opt/airflow/dags/scheduler.py for tasks to queue
[2022-12-17 04:47:07,791] {logging_mixin.py:109} INFO - [2022-12-17 04:47:07,790] {dagbag.py:500} INFO - Filling up the DagBag from /opt/airflow/dags/scheduler.py
[2022-12-17 04:47:07,957] {logging_mixin.py:109} INFO - [2022-12-17 04:47:07,950] {dagbag.py:334} ERROR - Failed to import: /opt/airflow/dags/scheduler.py
Traceback (most recent call last):
  File "/home/airflow/.local/lib/python3.7/site-packages/mysql/connector/connection_cext.py", line 236, in _open_connection
    self._cmysql.connect(**cnx_kwargs)
_mysql_connector.MySQLInterfaceError: Unknown MySQL server host 'warehouse' (-2)

During handling of the above exception, another exception occurred:

Traceback (most recent call last):
  File "/home/airflow/.local/lib/python3.7/site-packages/airflow/models/dagbag.py", line 331, in _load_modules_from_file
    loader.exec_module(new_module)
  File "<frozen importlib._bootstrap_external>", line 728, in exec_module
  File "<frozen importlib._bootstrap>", line 219, in _call_with_frames_removed
  File "/opt/airflow/dags/scheduler.py", line 17, in <module>
    connection = mysql.connector.connect(user=user, password=password, host=host, port=port, database=database, auth_plugin='mysql_native_password')
  File "/home/airflow/.local/lib/python3.7/site-packages/mysql/connector/__init__.py", line 272, in connect
    return CMySQLConnection(*args, **kwargs)
  File "/home/airflow/.local/lib/python3.7/site-packages/mysql/connector/connection_cext.py", line 85, in __init__
    self.connect(**kwargs)
  File "/home/airflow/.local/lib/python3.7/site-packages/mysql/connector/abstracts.py", line 1014, in connect
    self._open_connection()
  File "/home/airflow/.local/lib/python3.7/site-packages/mysql/connector/connection_cext.py", line 242, in _open_connection
    sqlstate=exc.sqlstate)
mysql.connector.errors.DatabaseError: 2005 (HY000): Unknown MySQL server host 'warehouse' (-2)
[2022-12-17 04:47:07,984] {processor.py:656} WARNING - No viable dags retrieved from /opt/airflow/dags/scheduler.py
[2022-12-17 04:47:08,005] {processor.py:171} INFO - Processing /opt/airflow/dags/scheduler.py took 0.225 seconds
[2022-12-17 04:47:38,059] {processor.py:163} INFO - Started process (PID=273) to work on /opt/airflow/dags/scheduler.py
[2022-12-17 04:47:38,062] {processor.py:642} INFO - Processing file /opt/airflow/dags/scheduler.py for tasks to queue
[2022-12-17 04:47:38,064] {logging_mixin.py:109} INFO - [2022-12-17 04:47:38,063] {dagbag.py:500} INFO - Filling up the DagBag from /opt/airflow/dags/scheduler.py
[2022-12-17 04:47:38,262] {logging_mixin.py:109} INFO - [2022-12-17 04:47:38,251] {dagbag.py:334} ERROR - Failed to import: /opt/airflow/dags/scheduler.py
Traceback (most recent call last):
  File "/home/airflow/.local/lib/python3.7/site-packages/mysql/connector/connection_cext.py", line 236, in _open_connection
    self._cmysql.connect(**cnx_kwargs)
_mysql_connector.MySQLInterfaceError: Unknown MySQL server host 'warehouse' (-2)

During handling of the above exception, another exception occurred:

Traceback (most recent call last):
  File "/home/airflow/.local/lib/python3.7/site-packages/airflow/models/dagbag.py", line 331, in _load_modules_from_file
    loader.exec_module(new_module)
  File "<frozen importlib._bootstrap_external>", line 728, in exec_module
  File "<frozen importlib._bootstrap>", line 219, in _call_with_frames_removed
  File "/opt/airflow/dags/scheduler.py", line 17, in <module>
    connection = mysql.connector.connect(user=user, password=password, host=host, port=port, database=database, auth_plugin='mysql_native_password')
  File "/home/airflow/.local/lib/python3.7/site-packages/mysql/connector/__init__.py", line 272, in connect
    return CMySQLConnection(*args, **kwargs)
  File "/home/airflow/.local/lib/python3.7/site-packages/mysql/connector/connection_cext.py", line 85, in __init__
    self.connect(**kwargs)
  File "/home/airflow/.local/lib/python3.7/site-packages/mysql/connector/abstracts.py", line 1014, in connect
    self._open_connection()
  File "/home/airflow/.local/lib/python3.7/site-packages/mysql/connector/connection_cext.py", line 242, in _open_connection
    sqlstate=exc.sqlstate)
mysql.connector.errors.DatabaseError: 2005 (HY000): Unknown MySQL server host 'warehouse' (-2)
[2022-12-17 04:47:38,293] {processor.py:656} WARNING - No viable dags retrieved from /opt/airflow/dags/scheduler.py
[2022-12-17 04:47:38,318] {processor.py:171} INFO - Processing /opt/airflow/dags/scheduler.py took 0.265 seconds
[2022-12-17 04:48:08,534] {processor.py:163} INFO - Started process (PID=300) to work on /opt/airflow/dags/scheduler.py
[2022-12-17 04:48:08,537] {processor.py:642} INFO - Processing file /opt/airflow/dags/scheduler.py for tasks to queue
[2022-12-17 04:48:08,540] {logging_mixin.py:109} INFO - [2022-12-17 04:48:08,539] {dagbag.py:500} INFO - Filling up the DagBag from /opt/airflow/dags/scheduler.py
[2022-12-17 04:48:08,730] {logging_mixin.py:109} INFO - [2022-12-17 04:48:08,723] {dagbag.py:334} ERROR - Failed to import: /opt/airflow/dags/scheduler.py
Traceback (most recent call last):
  File "/home/airflow/.local/lib/python3.7/site-packages/mysql/connector/connection_cext.py", line 236, in _open_connection
    self._cmysql.connect(**cnx_kwargs)
_mysql_connector.MySQLInterfaceError: Unknown MySQL server host 'warehouse' (-2)

During handling of the above exception, another exception occurred:

Traceback (most recent call last):
  File "/home/airflow/.local/lib/python3.7/site-packages/airflow/models/dagbag.py", line 331, in _load_modules_from_file
    loader.exec_module(new_module)
  File "<frozen importlib._bootstrap_external>", line 728, in exec_module
  File "<frozen importlib._bootstrap>", line 219, in _call_with_frames_removed
  File "/opt/airflow/dags/scheduler.py", line 17, in <module>
    connection = mysql.connector.connect(user=user, password=password, host=host, port=port, database=database, auth_plugin='mysql_native_password')
  File "/home/airflow/.local/lib/python3.7/site-packages/mysql/connector/__init__.py", line 272, in connect
    return CMySQLConnection(*args, **kwargs)
  File "/home/airflow/.local/lib/python3.7/site-packages/mysql/connector/connection_cext.py", line 85, in __init__
    self.connect(**kwargs)
  File "/home/airflow/.local/lib/python3.7/site-packages/mysql/connector/abstracts.py", line 1014, in connect
    self._open_connection()
  File "/home/airflow/.local/lib/python3.7/site-packages/mysql/connector/connection_cext.py", line 242, in _open_connection
    sqlstate=exc.sqlstate)
mysql.connector.errors.DatabaseError: 2005 (HY000): Unknown MySQL server host 'warehouse' (-2)
[2022-12-17 04:48:08,758] {processor.py:656} WARNING - No viable dags retrieved from /opt/airflow/dags/scheduler.py
[2022-12-17 04:48:08,778] {processor.py:171} INFO - Processing /opt/airflow/dags/scheduler.py took 0.251 seconds
[2022-12-17 04:48:38,947] {processor.py:163} INFO - Started process (PID=325) to work on /opt/airflow/dags/scheduler.py
[2022-12-17 04:48:38,951] {processor.py:642} INFO - Processing file /opt/airflow/dags/scheduler.py for tasks to queue
[2022-12-17 04:48:38,953] {logging_mixin.py:109} INFO - [2022-12-17 04:48:38,953] {dagbag.py:500} INFO - Filling up the DagBag from /opt/airflow/dags/scheduler.py
[2022-12-17 04:48:39,146] {logging_mixin.py:109} INFO - [2022-12-17 04:48:39,138] {dagbag.py:334} ERROR - Failed to import: /opt/airflow/dags/scheduler.py
Traceback (most recent call last):
  File "/home/airflow/.local/lib/python3.7/site-packages/mysql/connector/connection_cext.py", line 236, in _open_connection
    self._cmysql.connect(**cnx_kwargs)
_mysql_connector.MySQLInterfaceError: Unknown MySQL server host 'warehouse' (-2)

During handling of the above exception, another exception occurred:

Traceback (most recent call last):
  File "/home/airflow/.local/lib/python3.7/site-packages/airflow/models/dagbag.py", line 331, in _load_modules_from_file
    loader.exec_module(new_module)
  File "<frozen importlib._bootstrap_external>", line 728, in exec_module
  File "<frozen importlib._bootstrap>", line 219, in _call_with_frames_removed
  File "/opt/airflow/dags/scheduler.py", line 17, in <module>
    connection = mysql.connector.connect(user=user, password=password, host=host, port=port, database=database, auth_plugin='mysql_native_password')
  File "/home/airflow/.local/lib/python3.7/site-packages/mysql/connector/__init__.py", line 272, in connect
    return CMySQLConnection(*args, **kwargs)
  File "/home/airflow/.local/lib/python3.7/site-packages/mysql/connector/connection_cext.py", line 85, in __init__
    self.connect(**kwargs)
  File "/home/airflow/.local/lib/python3.7/site-packages/mysql/connector/abstracts.py", line 1014, in connect
    self._open_connection()
  File "/home/airflow/.local/lib/python3.7/site-packages/mysql/connector/connection_cext.py", line 242, in _open_connection
    sqlstate=exc.sqlstate)
mysql.connector.errors.DatabaseError: 2005 (HY000): Unknown MySQL server host 'warehouse' (-2)
[2022-12-17 04:48:39,173] {processor.py:656} WARNING - No viable dags retrieved from /opt/airflow/dags/scheduler.py
[2022-12-17 04:48:39,198] {processor.py:171} INFO - Processing /opt/airflow/dags/scheduler.py took 0.257 seconds
[2022-12-17 04:49:09,269] {processor.py:163} INFO - Started process (PID=359) to work on /opt/airflow/dags/scheduler.py
[2022-12-17 04:49:09,274] {processor.py:642} INFO - Processing file /opt/airflow/dags/scheduler.py for tasks to queue
[2022-12-17 04:49:09,277] {logging_mixin.py:109} INFO - [2022-12-17 04:49:09,276] {dagbag.py:500} INFO - Filling up the DagBag from /opt/airflow/dags/scheduler.py
[2022-12-17 04:49:09,494] {logging_mixin.py:109} INFO - [2022-12-17 04:49:09,485] {dagbag.py:334} ERROR - Failed to import: /opt/airflow/dags/scheduler.py
Traceback (most recent call last):
  File "/home/airflow/.local/lib/python3.7/site-packages/mysql/connector/connection_cext.py", line 236, in _open_connection
    self._cmysql.connect(**cnx_kwargs)
_mysql_connector.MySQLInterfaceError: Unknown MySQL server host 'warehouse' (-2)

During handling of the above exception, another exception occurred:

Traceback (most recent call last):
  File "/home/airflow/.local/lib/python3.7/site-packages/airflow/models/dagbag.py", line 331, in _load_modules_from_file
    loader.exec_module(new_module)
  File "<frozen importlib._bootstrap_external>", line 728, in exec_module
  File "<frozen importlib._bootstrap>", line 219, in _call_with_frames_removed
  File "/opt/airflow/dags/scheduler.py", line 17, in <module>
    connection = mysql.connector.connect(user=user, password=password, host=host, port=port, database=database, auth_plugin='mysql_native_password')
  File "/home/airflow/.local/lib/python3.7/site-packages/mysql/connector/__init__.py", line 272, in connect
    return CMySQLConnection(*args, **kwargs)
  File "/home/airflow/.local/lib/python3.7/site-packages/mysql/connector/connection_cext.py", line 85, in __init__
    self.connect(**kwargs)
  File "/home/airflow/.local/lib/python3.7/site-packages/mysql/connector/abstracts.py", line 1014, in connect
    self._open_connection()
  File "/home/airflow/.local/lib/python3.7/site-packages/mysql/connector/connection_cext.py", line 242, in _open_connection
    sqlstate=exc.sqlstate)
mysql.connector.errors.DatabaseError: 2005 (HY000): Unknown MySQL server host 'warehouse' (-2)
[2022-12-17 04:49:09,546] {processor.py:656} WARNING - No viable dags retrieved from /opt/airflow/dags/scheduler.py
[2022-12-17 04:49:09,572] {processor.py:171} INFO - Processing /opt/airflow/dags/scheduler.py took 0.311 seconds
[2022-12-17 04:49:39,631] {processor.py:163} INFO - Started process (PID=377) to work on /opt/airflow/dags/scheduler.py
[2022-12-17 04:49:39,635] {processor.py:642} INFO - Processing file /opt/airflow/dags/scheduler.py for tasks to queue
[2022-12-17 04:49:39,637] {logging_mixin.py:109} INFO - [2022-12-17 04:49:39,637] {dagbag.py:500} INFO - Filling up the DagBag from /opt/airflow/dags/scheduler.py
[2022-12-17 04:49:39,811] {logging_mixin.py:109} INFO - [2022-12-17 04:49:39,804] {dagbag.py:334} ERROR - Failed to import: /opt/airflow/dags/scheduler.py
Traceback (most recent call last):
  File "/home/airflow/.local/lib/python3.7/site-packages/mysql/connector/connection_cext.py", line 236, in _open_connection
    self._cmysql.connect(**cnx_kwargs)
_mysql_connector.MySQLInterfaceError: Unknown MySQL server host 'warehouse' (-2)

During handling of the above exception, another exception occurred:

Traceback (most recent call last):
  File "/home/airflow/.local/lib/python3.7/site-packages/airflow/models/dagbag.py", line 331, in _load_modules_from_file
    loader.exec_module(new_module)
  File "<frozen importlib._bootstrap_external>", line 728, in exec_module
  File "<frozen importlib._bootstrap>", line 219, in _call_with_frames_removed
  File "/opt/airflow/dags/scheduler.py", line 17, in <module>
    connection = mysql.connector.connect(user=user, password=password, host=host, port=port, database=database, auth_plugin='mysql_native_password')
  File "/home/airflow/.local/lib/python3.7/site-packages/mysql/connector/__init__.py", line 272, in connect
    return CMySQLConnection(*args, **kwargs)
  File "/home/airflow/.local/lib/python3.7/site-packages/mysql/connector/connection_cext.py", line 85, in __init__
    self.connect(**kwargs)
  File "/home/airflow/.local/lib/python3.7/site-packages/mysql/connector/abstracts.py", line 1014, in connect
    self._open_connection()
  File "/home/airflow/.local/lib/python3.7/site-packages/mysql/connector/connection_cext.py", line 242, in _open_connection
    sqlstate=exc.sqlstate)
mysql.connector.errors.DatabaseError: 2005 (HY000): Unknown MySQL server host 'warehouse' (-2)
[2022-12-17 04:49:39,839] {processor.py:656} WARNING - No viable dags retrieved from /opt/airflow/dags/scheduler.py
[2022-12-17 04:49:39,862] {processor.py:171} INFO - Processing /opt/airflow/dags/scheduler.py took 0.236 seconds
[2022-12-17 04:50:10,092] {processor.py:163} INFO - Started process (PID=411) to work on /opt/airflow/dags/scheduler.py
[2022-12-17 04:50:10,095] {processor.py:642} INFO - Processing file /opt/airflow/dags/scheduler.py for tasks to queue
[2022-12-17 04:50:10,097] {logging_mixin.py:109} INFO - [2022-12-17 04:50:10,097] {dagbag.py:500} INFO - Filling up the DagBag from /opt/airflow/dags/scheduler.py
[2022-12-17 04:50:10,282] {logging_mixin.py:109} INFO - [2022-12-17 04:50:10,263] {dagbag.py:334} ERROR - Failed to import: /opt/airflow/dags/scheduler.py
Traceback (most recent call last):
  File "/home/airflow/.local/lib/python3.7/site-packages/mysql/connector/connection_cext.py", line 236, in _open_connection
    self._cmysql.connect(**cnx_kwargs)
_mysql_connector.MySQLInterfaceError: Unknown MySQL server host 'warehouse' (-2)

During handling of the above exception, another exception occurred:

Traceback (most recent call last):
  File "/home/airflow/.local/lib/python3.7/site-packages/airflow/models/dagbag.py", line 331, in _load_modules_from_file
    loader.exec_module(new_module)
  File "<frozen importlib._bootstrap_external>", line 728, in exec_module
  File "<frozen importlib._bootstrap>", line 219, in _call_with_frames_removed
  File "/opt/airflow/dags/scheduler.py", line 17, in <module>
    connection = mysql.connector.connect(user=user, password=password, host=host, port=port, database=database, auth_plugin='mysql_native_password')
  File "/home/airflow/.local/lib/python3.7/site-packages/mysql/connector/__init__.py", line 272, in connect
    return CMySQLConnection(*args, **kwargs)
  File "/home/airflow/.local/lib/python3.7/site-packages/mysql/connector/connection_cext.py", line 85, in __init__
    self.connect(**kwargs)
  File "/home/airflow/.local/lib/python3.7/site-packages/mysql/connector/abstracts.py", line 1014, in connect
    self._open_connection()
  File "/home/airflow/.local/lib/python3.7/site-packages/mysql/connector/connection_cext.py", line 242, in _open_connection
    sqlstate=exc.sqlstate)
mysql.connector.errors.DatabaseError: 2005 (HY000): Unknown MySQL server host 'warehouse' (-2)
[2022-12-17 04:50:10,328] {processor.py:656} WARNING - No viable dags retrieved from /opt/airflow/dags/scheduler.py
[2022-12-17 04:50:10,349] {processor.py:171} INFO - Processing /opt/airflow/dags/scheduler.py took 0.263 seconds
[2022-12-17 04:50:40,506] {processor.py:163} INFO - Started process (PID=429) to work on /opt/airflow/dags/scheduler.py
[2022-12-17 04:50:40,509] {processor.py:642} INFO - Processing file /opt/airflow/dags/scheduler.py for tasks to queue
[2022-12-17 04:50:40,511] {logging_mixin.py:109} INFO - [2022-12-17 04:50:40,511] {dagbag.py:500} INFO - Filling up the DagBag from /opt/airflow/dags/scheduler.py
[2022-12-17 04:50:40,684] {logging_mixin.py:109} INFO - [2022-12-17 04:50:40,676] {dagbag.py:334} ERROR - Failed to import: /opt/airflow/dags/scheduler.py
Traceback (most recent call last):
  File "/home/airflow/.local/lib/python3.7/site-packages/mysql/connector/connection_cext.py", line 236, in _open_connection
    self._cmysql.connect(**cnx_kwargs)
_mysql_connector.MySQLInterfaceError: Unknown MySQL server host 'warehouse' (-2)

During handling of the above exception, another exception occurred:

Traceback (most recent call last):
  File "/home/airflow/.local/lib/python3.7/site-packages/airflow/models/dagbag.py", line 331, in _load_modules_from_file
    loader.exec_module(new_module)
  File "<frozen importlib._bootstrap_external>", line 728, in exec_module
  File "<frozen importlib._bootstrap>", line 219, in _call_with_frames_removed
  File "/opt/airflow/dags/scheduler.py", line 17, in <module>
    connection = mysql.connector.connect(user=user, password=password, host=host, port=port, database=database, auth_plugin='mysql_native_password')
  File "/home/airflow/.local/lib/python3.7/site-packages/mysql/connector/__init__.py", line 272, in connect
    return CMySQLConnection(*args, **kwargs)
  File "/home/airflow/.local/lib/python3.7/site-packages/mysql/connector/connection_cext.py", line 85, in __init__
    self.connect(**kwargs)
  File "/home/airflow/.local/lib/python3.7/site-packages/mysql/connector/abstracts.py", line 1014, in connect
    self._open_connection()
  File "/home/airflow/.local/lib/python3.7/site-packages/mysql/connector/connection_cext.py", line 242, in _open_connection
    sqlstate=exc.sqlstate)
mysql.connector.errors.DatabaseError: 2005 (HY000): Unknown MySQL server host 'warehouse' (-2)
[2022-12-17 04:50:40,711] {processor.py:656} WARNING - No viable dags retrieved from /opt/airflow/dags/scheduler.py
[2022-12-17 04:50:40,732] {processor.py:171} INFO - Processing /opt/airflow/dags/scheduler.py took 0.233 seconds
[2022-12-17 04:51:10,927] {processor.py:163} INFO - Started process (PID=463) to work on /opt/airflow/dags/scheduler.py
[2022-12-17 04:51:10,930] {processor.py:642} INFO - Processing file /opt/airflow/dags/scheduler.py for tasks to queue
[2022-12-17 04:51:10,932] {logging_mixin.py:109} INFO - [2022-12-17 04:51:10,932] {dagbag.py:500} INFO - Filling up the DagBag from /opt/airflow/dags/scheduler.py
[2022-12-17 04:51:11,106] {logging_mixin.py:109} INFO - [2022-12-17 04:51:11,098] {dagbag.py:334} ERROR - Failed to import: /opt/airflow/dags/scheduler.py
Traceback (most recent call last):
  File "/home/airflow/.local/lib/python3.7/site-packages/mysql/connector/connection_cext.py", line 236, in _open_connection
    self._cmysql.connect(**cnx_kwargs)
_mysql_connector.MySQLInterfaceError: Unknown MySQL server host 'warehouse' (-2)

During handling of the above exception, another exception occurred:

Traceback (most recent call last):
  File "/home/airflow/.local/lib/python3.7/site-packages/airflow/models/dagbag.py", line 331, in _load_modules_from_file
    loader.exec_module(new_module)
  File "<frozen importlib._bootstrap_external>", line 728, in exec_module
  File "<frozen importlib._bootstrap>", line 219, in _call_with_frames_removed
  File "/opt/airflow/dags/scheduler.py", line 17, in <module>
    connection = mysql.connector.connect(user=user, password=password, host=host, port=port, database=database, auth_plugin='mysql_native_password')
  File "/home/airflow/.local/lib/python3.7/site-packages/mysql/connector/__init__.py", line 272, in connect
    return CMySQLConnection(*args, **kwargs)
  File "/home/airflow/.local/lib/python3.7/site-packages/mysql/connector/connection_cext.py", line 85, in __init__
    self.connect(**kwargs)
  File "/home/airflow/.local/lib/python3.7/site-packages/mysql/connector/abstracts.py", line 1014, in connect
    self._open_connection()
  File "/home/airflow/.local/lib/python3.7/site-packages/mysql/connector/connection_cext.py", line 242, in _open_connection
    sqlstate=exc.sqlstate)
mysql.connector.errors.DatabaseError: 2005 (HY000): Unknown MySQL server host 'warehouse' (-2)
[2022-12-17 04:51:11,133] {processor.py:656} WARNING - No viable dags retrieved from /opt/airflow/dags/scheduler.py
[2022-12-17 04:51:11,154] {processor.py:171} INFO - Processing /opt/airflow/dags/scheduler.py took 0.234 seconds
[2022-12-17 04:51:41,331] {processor.py:163} INFO - Started process (PID=481) to work on /opt/airflow/dags/scheduler.py
[2022-12-17 04:51:41,336] {processor.py:642} INFO - Processing file /opt/airflow/dags/scheduler.py for tasks to queue
[2022-12-17 04:51:41,338] {logging_mixin.py:109} INFO - [2022-12-17 04:51:41,337] {dagbag.py:500} INFO - Filling up the DagBag from /opt/airflow/dags/scheduler.py
[2022-12-17 04:51:41,534] {logging_mixin.py:109} INFO - [2022-12-17 04:51:41,527] {dagbag.py:334} ERROR - Failed to import: /opt/airflow/dags/scheduler.py
Traceback (most recent call last):
  File "/home/airflow/.local/lib/python3.7/site-packages/mysql/connector/connection_cext.py", line 236, in _open_connection
    self._cmysql.connect(**cnx_kwargs)
_mysql_connector.MySQLInterfaceError: Unknown MySQL server host 'warehouse' (-2)

During handling of the above exception, another exception occurred:

Traceback (most recent call last):
  File "/home/airflow/.local/lib/python3.7/site-packages/airflow/models/dagbag.py", line 331, in _load_modules_from_file
    loader.exec_module(new_module)
  File "<frozen importlib._bootstrap_external>", line 728, in exec_module
  File "<frozen importlib._bootstrap>", line 219, in _call_with_frames_removed
  File "/opt/airflow/dags/scheduler.py", line 17, in <module>
    connection = mysql.connector.connect(user=user, password=password, host=host, port=port, database=database, auth_plugin='mysql_native_password')
  File "/home/airflow/.local/lib/python3.7/site-packages/mysql/connector/__init__.py", line 272, in connect
    return CMySQLConnection(*args, **kwargs)
  File "/home/airflow/.local/lib/python3.7/site-packages/mysql/connector/connection_cext.py", line 85, in __init__
    self.connect(**kwargs)
  File "/home/airflow/.local/lib/python3.7/site-packages/mysql/connector/abstracts.py", line 1014, in connect
    self._open_connection()
  File "/home/airflow/.local/lib/python3.7/site-packages/mysql/connector/connection_cext.py", line 242, in _open_connection
    sqlstate=exc.sqlstate)
mysql.connector.errors.DatabaseError: 2005 (HY000): Unknown MySQL server host 'warehouse' (-2)
[2022-12-17 04:51:41,562] {processor.py:656} WARNING - No viable dags retrieved from /opt/airflow/dags/scheduler.py
[2022-12-17 04:51:41,584] {processor.py:171} INFO - Processing /opt/airflow/dags/scheduler.py took 0.260 seconds
[2022-12-17 04:52:11,781] {processor.py:163} INFO - Started process (PID=516) to work on /opt/airflow/dags/scheduler.py
[2022-12-17 04:52:11,784] {processor.py:642} INFO - Processing file /opt/airflow/dags/scheduler.py for tasks to queue
[2022-12-17 04:52:11,786] {logging_mixin.py:109} INFO - [2022-12-17 04:52:11,786] {dagbag.py:500} INFO - Filling up the DagBag from /opt/airflow/dags/scheduler.py
[2022-12-17 04:52:11,957] {logging_mixin.py:109} INFO - [2022-12-17 04:52:11,949] {dagbag.py:334} ERROR - Failed to import: /opt/airflow/dags/scheduler.py
Traceback (most recent call last):
  File "/home/airflow/.local/lib/python3.7/site-packages/mysql/connector/connection_cext.py", line 236, in _open_connection
    self._cmysql.connect(**cnx_kwargs)
_mysql_connector.MySQLInterfaceError: Unknown MySQL server host 'warehouse' (-2)

During handling of the above exception, another exception occurred:

Traceback (most recent call last):
  File "/home/airflow/.local/lib/python3.7/site-packages/airflow/models/dagbag.py", line 331, in _load_modules_from_file
    loader.exec_module(new_module)
  File "<frozen importlib._bootstrap_external>", line 728, in exec_module
  File "<frozen importlib._bootstrap>", line 219, in _call_with_frames_removed
  File "/opt/airflow/dags/scheduler.py", line 17, in <module>
    connection = mysql.connector.connect(user=user, password=password, host=host, port=port, database=database, auth_plugin='mysql_native_password')
  File "/home/airflow/.local/lib/python3.7/site-packages/mysql/connector/__init__.py", line 272, in connect
    return CMySQLConnection(*args, **kwargs)
  File "/home/airflow/.local/lib/python3.7/site-packages/mysql/connector/connection_cext.py", line 85, in __init__
    self.connect(**kwargs)
  File "/home/airflow/.local/lib/python3.7/site-packages/mysql/connector/abstracts.py", line 1014, in connect
    self._open_connection()
  File "/home/airflow/.local/lib/python3.7/site-packages/mysql/connector/connection_cext.py", line 242, in _open_connection
    sqlstate=exc.sqlstate)
mysql.connector.errors.DatabaseError: 2005 (HY000): Unknown MySQL server host 'warehouse' (-2)
[2022-12-17 04:52:11,984] {processor.py:656} WARNING - No viable dags retrieved from /opt/airflow/dags/scheduler.py
[2022-12-17 04:52:12,007] {processor.py:171} INFO - Processing /opt/airflow/dags/scheduler.py took 0.233 seconds
[2022-12-17 04:52:42,219] {processor.py:163} INFO - Started process (PID=534) to work on /opt/airflow/dags/scheduler.py
[2022-12-17 04:52:42,224] {processor.py:642} INFO - Processing file /opt/airflow/dags/scheduler.py for tasks to queue
[2022-12-17 04:52:42,227] {logging_mixin.py:109} INFO - [2022-12-17 04:52:42,227] {dagbag.py:500} INFO - Filling up the DagBag from /opt/airflow/dags/scheduler.py
[2022-12-17 04:52:42,394] {logging_mixin.py:109} INFO - [2022-12-17 04:52:42,387] {dagbag.py:334} ERROR - Failed to import: /opt/airflow/dags/scheduler.py
Traceback (most recent call last):
  File "/home/airflow/.local/lib/python3.7/site-packages/mysql/connector/connection_cext.py", line 236, in _open_connection
    self._cmysql.connect(**cnx_kwargs)
_mysql_connector.MySQLInterfaceError: Unknown MySQL server host 'warehouse' (-2)

During handling of the above exception, another exception occurred:

Traceback (most recent call last):
  File "/home/airflow/.local/lib/python3.7/site-packages/airflow/models/dagbag.py", line 331, in _load_modules_from_file
    loader.exec_module(new_module)
  File "<frozen importlib._bootstrap_external>", line 728, in exec_module
  File "<frozen importlib._bootstrap>", line 219, in _call_with_frames_removed
  File "/opt/airflow/dags/scheduler.py", line 17, in <module>
    connection = mysql.connector.connect(user=user, password=password, host=host, port=port, database=database, auth_plugin='mysql_native_password')
  File "/home/airflow/.local/lib/python3.7/site-packages/mysql/connector/__init__.py", line 272, in connect
    return CMySQLConnection(*args, **kwargs)
  File "/home/airflow/.local/lib/python3.7/site-packages/mysql/connector/connection_cext.py", line 85, in __init__
    self.connect(**kwargs)
  File "/home/airflow/.local/lib/python3.7/site-packages/mysql/connector/abstracts.py", line 1014, in connect
    self._open_connection()
  File "/home/airflow/.local/lib/python3.7/site-packages/mysql/connector/connection_cext.py", line 242, in _open_connection
    sqlstate=exc.sqlstate)
mysql.connector.errors.DatabaseError: 2005 (HY000): Unknown MySQL server host 'warehouse' (-2)
[2022-12-17 04:52:42,420] {processor.py:656} WARNING - No viable dags retrieved from /opt/airflow/dags/scheduler.py
[2022-12-17 04:52:42,439] {processor.py:171} INFO - Processing /opt/airflow/dags/scheduler.py took 0.231 seconds
[2022-12-17 04:53:12,602] {processor.py:163} INFO - Started process (PID=568) to work on /opt/airflow/dags/scheduler.py
[2022-12-17 04:53:12,605] {processor.py:642} INFO - Processing file /opt/airflow/dags/scheduler.py for tasks to queue
[2022-12-17 04:53:12,607] {logging_mixin.py:109} INFO - [2022-12-17 04:53:12,607] {dagbag.py:500} INFO - Filling up the DagBag from /opt/airflow/dags/scheduler.py
[2022-12-17 04:53:12,941] {logging_mixin.py:109} INFO - [2022-12-17 04:53:12,934] {dagbag.py:334} ERROR - Failed to import: /opt/airflow/dags/scheduler.py
Traceback (most recent call last):
  File "/home/airflow/.local/lib/python3.7/site-packages/mysql/connector/connection_cext.py", line 236, in _open_connection
    self._cmysql.connect(**cnx_kwargs)
_mysql_connector.MySQLInterfaceError: Unknown MySQL server host 'warehouse' (-2)

During handling of the above exception, another exception occurred:

Traceback (most recent call last):
  File "/home/airflow/.local/lib/python3.7/site-packages/airflow/models/dagbag.py", line 331, in _load_modules_from_file
    loader.exec_module(new_module)
  File "<frozen importlib._bootstrap_external>", line 728, in exec_module
  File "<frozen importlib._bootstrap>", line 219, in _call_with_frames_removed
  File "/opt/airflow/dags/scheduler.py", line 17, in <module>
    connection = mysql.connector.connect(user=user, password=password, host=host, port=port, database=database, auth_plugin='mysql_native_password')
  File "/home/airflow/.local/lib/python3.7/site-packages/mysql/connector/__init__.py", line 272, in connect
    return CMySQLConnection(*args, **kwargs)
  File "/home/airflow/.local/lib/python3.7/site-packages/mysql/connector/connection_cext.py", line 85, in __init__
    self.connect(**kwargs)
  File "/home/airflow/.local/lib/python3.7/site-packages/mysql/connector/abstracts.py", line 1014, in connect
    self._open_connection()
  File "/home/airflow/.local/lib/python3.7/site-packages/mysql/connector/connection_cext.py", line 242, in _open_connection
    sqlstate=exc.sqlstate)
mysql.connector.errors.DatabaseError: 2005 (HY000): Unknown MySQL server host 'warehouse' (-2)
[2022-12-17 04:53:12,972] {processor.py:656} WARNING - No viable dags retrieved from /opt/airflow/dags/scheduler.py
[2022-12-17 04:53:12,995] {processor.py:171} INFO - Processing /opt/airflow/dags/scheduler.py took 0.399 seconds
[2022-12-17 04:53:43,153] {processor.py:163} INFO - Started process (PID=596) to work on /opt/airflow/dags/scheduler.py
[2022-12-17 04:53:43,157] {processor.py:642} INFO - Processing file /opt/airflow/dags/scheduler.py for tasks to queue
[2022-12-17 04:53:43,159] {logging_mixin.py:109} INFO - [2022-12-17 04:53:43,159] {dagbag.py:500} INFO - Filling up the DagBag from /opt/airflow/dags/scheduler.py
[2022-12-17 04:53:43,340] {logging_mixin.py:109} INFO - [2022-12-17 04:53:43,334] {dagbag.py:334} ERROR - Failed to import: /opt/airflow/dags/scheduler.py
Traceback (most recent call last):
  File "/home/airflow/.local/lib/python3.7/site-packages/mysql/connector/connection_cext.py", line 236, in _open_connection
    self._cmysql.connect(**cnx_kwargs)
_mysql_connector.MySQLInterfaceError: Unknown MySQL server host 'warehouse' (-2)

During handling of the above exception, another exception occurred:

Traceback (most recent call last):
  File "/home/airflow/.local/lib/python3.7/site-packages/airflow/models/dagbag.py", line 331, in _load_modules_from_file
    loader.exec_module(new_module)
  File "<frozen importlib._bootstrap_external>", line 728, in exec_module
  File "<frozen importlib._bootstrap>", line 219, in _call_with_frames_removed
  File "/opt/airflow/dags/scheduler.py", line 17, in <module>
    connection = mysql.connector.connect(user=user, password=password, host=host, port=port, database=database, auth_plugin='mysql_native_password')
  File "/home/airflow/.local/lib/python3.7/site-packages/mysql/connector/__init__.py", line 272, in connect
    return CMySQLConnection(*args, **kwargs)
  File "/home/airflow/.local/lib/python3.7/site-packages/mysql/connector/connection_cext.py", line 85, in __init__
    self.connect(**kwargs)
  File "/home/airflow/.local/lib/python3.7/site-packages/mysql/connector/abstracts.py", line 1014, in connect
    self._open_connection()
  File "/home/airflow/.local/lib/python3.7/site-packages/mysql/connector/connection_cext.py", line 242, in _open_connection
    sqlstate=exc.sqlstate)
mysql.connector.errors.DatabaseError: 2005 (HY000): Unknown MySQL server host 'warehouse' (-2)
[2022-12-17 04:53:43,368] {processor.py:656} WARNING - No viable dags retrieved from /opt/airflow/dags/scheduler.py
[2022-12-17 04:53:43,391] {processor.py:171} INFO - Processing /opt/airflow/dags/scheduler.py took 0.245 seconds
[2022-12-17 04:54:13,531] {processor.py:163} INFO - Started process (PID=620) to work on /opt/airflow/dags/scheduler.py
[2022-12-17 04:54:13,535] {processor.py:642} INFO - Processing file /opt/airflow/dags/scheduler.py for tasks to queue
[2022-12-17 04:54:13,538] {logging_mixin.py:109} INFO - [2022-12-17 04:54:13,538] {dagbag.py:500} INFO - Filling up the DagBag from /opt/airflow/dags/scheduler.py
[2022-12-17 04:54:13,706] {logging_mixin.py:109} INFO - [2022-12-17 04:54:13,700] {dagbag.py:334} ERROR - Failed to import: /opt/airflow/dags/scheduler.py
Traceback (most recent call last):
  File "/home/airflow/.local/lib/python3.7/site-packages/mysql/connector/connection_cext.py", line 236, in _open_connection
    self._cmysql.connect(**cnx_kwargs)
_mysql_connector.MySQLInterfaceError: Unknown MySQL server host 'warehouse' (-2)

During handling of the above exception, another exception occurred:

Traceback (most recent call last):
  File "/home/airflow/.local/lib/python3.7/site-packages/airflow/models/dagbag.py", line 331, in _load_modules_from_file
    loader.exec_module(new_module)
  File "<frozen importlib._bootstrap_external>", line 728, in exec_module
  File "<frozen importlib._bootstrap>", line 219, in _call_with_frames_removed
  File "/opt/airflow/dags/scheduler.py", line 17, in <module>
    connection = mysql.connector.connect(user=user, password=password, host=host, port=port, database=database, auth_plugin='mysql_native_password')
  File "/home/airflow/.local/lib/python3.7/site-packages/mysql/connector/__init__.py", line 272, in connect
    return CMySQLConnection(*args, **kwargs)
  File "/home/airflow/.local/lib/python3.7/site-packages/mysql/connector/connection_cext.py", line 85, in __init__
    self.connect(**kwargs)
  File "/home/airflow/.local/lib/python3.7/site-packages/mysql/connector/abstracts.py", line 1014, in connect
    self._open_connection()
  File "/home/airflow/.local/lib/python3.7/site-packages/mysql/connector/connection_cext.py", line 242, in _open_connection
    sqlstate=exc.sqlstate)
mysql.connector.errors.DatabaseError: 2005 (HY000): Unknown MySQL server host 'warehouse' (-2)
[2022-12-17 04:54:13,736] {processor.py:656} WARNING - No viable dags retrieved from /opt/airflow/dags/scheduler.py
[2022-12-17 04:54:13,757] {processor.py:171} INFO - Processing /opt/airflow/dags/scheduler.py took 0.233 seconds
[2022-12-17 04:54:43,806] {processor.py:163} INFO - Started process (PID=654) to work on /opt/airflow/dags/scheduler.py
[2022-12-17 04:54:43,810] {processor.py:642} INFO - Processing file /opt/airflow/dags/scheduler.py for tasks to queue
[2022-12-17 04:54:43,812] {logging_mixin.py:109} INFO - [2022-12-17 04:54:43,811] {dagbag.py:500} INFO - Filling up the DagBag from /opt/airflow/dags/scheduler.py
[2022-12-17 04:54:43,994] {logging_mixin.py:109} INFO - [2022-12-17 04:54:43,986] {dagbag.py:334} ERROR - Failed to import: /opt/airflow/dags/scheduler.py
Traceback (most recent call last):
  File "/home/airflow/.local/lib/python3.7/site-packages/mysql/connector/connection_cext.py", line 236, in _open_connection
    self._cmysql.connect(**cnx_kwargs)
_mysql_connector.MySQLInterfaceError: Unknown MySQL server host 'warehouse' (-2)

During handling of the above exception, another exception occurred:

Traceback (most recent call last):
  File "/home/airflow/.local/lib/python3.7/site-packages/airflow/models/dagbag.py", line 331, in _load_modules_from_file
    loader.exec_module(new_module)
  File "<frozen importlib._bootstrap_external>", line 728, in exec_module
  File "<frozen importlib._bootstrap>", line 219, in _call_with_frames_removed
  File "/opt/airflow/dags/scheduler.py", line 17, in <module>
    connection = mysql.connector.connect(user=user, password=password, host=host, port=port, database=database, auth_plugin='mysql_native_password')
  File "/home/airflow/.local/lib/python3.7/site-packages/mysql/connector/__init__.py", line 272, in connect
    return CMySQLConnection(*args, **kwargs)
  File "/home/airflow/.local/lib/python3.7/site-packages/mysql/connector/connection_cext.py", line 85, in __init__
    self.connect(**kwargs)
  File "/home/airflow/.local/lib/python3.7/site-packages/mysql/connector/abstracts.py", line 1014, in connect
    self._open_connection()
  File "/home/airflow/.local/lib/python3.7/site-packages/mysql/connector/connection_cext.py", line 242, in _open_connection
    sqlstate=exc.sqlstate)
mysql.connector.errors.DatabaseError: 2005 (HY000): Unknown MySQL server host 'warehouse' (-2)
[2022-12-17 04:54:44,022] {processor.py:656} WARNING - No viable dags retrieved from /opt/airflow/dags/scheduler.py
[2022-12-17 04:54:44,210] {processor.py:171} INFO - Processing /opt/airflow/dags/scheduler.py took 0.411 seconds
[2022-12-17 05:07:14,680] {processor.py:163} INFO - Started process (PID=136) to work on /opt/airflow/dags/scheduler.py
[2022-12-17 05:07:14,691] {processor.py:642} INFO - Processing file /opt/airflow/dags/scheduler.py for tasks to queue
[2022-12-17 05:07:14,700] {logging_mixin.py:109} INFO - [2022-12-17 05:07:14,699] {dagbag.py:500} INFO - Filling up the DagBag from /opt/airflow/dags/scheduler.py
[2022-12-17 05:07:16,525] {logging_mixin.py:109} INFO - [2022-12-17 05:07:16,504] {dagbag.py:334} ERROR - Failed to import: /opt/airflow/dags/scheduler.py
Traceback (most recent call last):
  File "/home/airflow/.local/lib/python3.7/site-packages/mysql/connector/connection_cext.py", line 236, in _open_connection
    self._cmysql.connect(**cnx_kwargs)
_mysql_connector.MySQLInterfaceError: Access denied for user 'airflow'@'172.24.0.7' (using password: NO)

During handling of the above exception, another exception occurred:

Traceback (most recent call last):
  File "/home/airflow/.local/lib/python3.7/site-packages/airflow/models/dagbag.py", line 331, in _load_modules_from_file
    loader.exec_module(new_module)
  File "<frozen importlib._bootstrap_external>", line 728, in exec_module
  File "<frozen importlib._bootstrap>", line 219, in _call_with_frames_removed
  File "/opt/airflow/dags/scheduler.py", line 17, in <module>
    connection = mysql.connector.connect(user=user, password=password, host=host, port=port, database=database, auth_plugin='mysql_native_password')
  File "/home/airflow/.local/lib/python3.7/site-packages/mysql/connector/__init__.py", line 272, in connect
    return CMySQLConnection(*args, **kwargs)
  File "/home/airflow/.local/lib/python3.7/site-packages/mysql/connector/connection_cext.py", line 85, in __init__
    self.connect(**kwargs)
  File "/home/airflow/.local/lib/python3.7/site-packages/mysql/connector/abstracts.py", line 1014, in connect
    self._open_connection()
  File "/home/airflow/.local/lib/python3.7/site-packages/mysql/connector/connection_cext.py", line 242, in _open_connection
    sqlstate=exc.sqlstate)
mysql.connector.errors.ProgrammingError: 1045 (28000): Access denied for user 'airflow'@'172.24.0.7' (using password: NO)
[2022-12-17 05:07:16,569] {processor.py:656} WARNING - No viable dags retrieved from /opt/airflow/dags/scheduler.py
[2022-12-17 05:07:16,614] {processor.py:171} INFO - Processing /opt/airflow/dags/scheduler.py took 1.952 seconds
[2022-12-17 05:07:47,111] {processor.py:163} INFO - Started process (PID=170) to work on /opt/airflow/dags/scheduler.py
[2022-12-17 05:07:47,124] {processor.py:642} INFO - Processing file /opt/airflow/dags/scheduler.py for tasks to queue
[2022-12-17 05:07:47,126] {logging_mixin.py:109} INFO - [2022-12-17 05:07:47,126] {dagbag.py:500} INFO - Filling up the DagBag from /opt/airflow/dags/scheduler.py
[2022-12-17 05:07:47,684] {logging_mixin.py:109} INFO - [2022-12-17 05:07:47,661] {dagbag.py:334} ERROR - Failed to import: /opt/airflow/dags/scheduler.py
Traceback (most recent call last):
  File "/home/airflow/.local/lib/python3.7/site-packages/mysql/connector/connection_cext.py", line 236, in _open_connection
    self._cmysql.connect(**cnx_kwargs)
_mysql_connector.MySQLInterfaceError: Access denied for user 'airflow'@'172.24.0.7' (using password: NO)

During handling of the above exception, another exception occurred:

Traceback (most recent call last):
  File "/home/airflow/.local/lib/python3.7/site-packages/airflow/models/dagbag.py", line 331, in _load_modules_from_file
    loader.exec_module(new_module)
  File "<frozen importlib._bootstrap_external>", line 728, in exec_module
  File "<frozen importlib._bootstrap>", line 219, in _call_with_frames_removed
  File "/opt/airflow/dags/scheduler.py", line 17, in <module>
    connection = mysql.connector.connect(user=user, password=password, host=host, port=port, database=database, auth_plugin='mysql_native_password')
  File "/home/airflow/.local/lib/python3.7/site-packages/mysql/connector/__init__.py", line 272, in connect
    return CMySQLConnection(*args, **kwargs)
  File "/home/airflow/.local/lib/python3.7/site-packages/mysql/connector/connection_cext.py", line 85, in __init__
    self.connect(**kwargs)
  File "/home/airflow/.local/lib/python3.7/site-packages/mysql/connector/abstracts.py", line 1014, in connect
    self._open_connection()
  File "/home/airflow/.local/lib/python3.7/site-packages/mysql/connector/connection_cext.py", line 242, in _open_connection
    sqlstate=exc.sqlstate)
mysql.connector.errors.ProgrammingError: 1045 (28000): Access denied for user 'airflow'@'172.24.0.7' (using password: NO)
[2022-12-17 05:07:47,738] {processor.py:656} WARNING - No viable dags retrieved from /opt/airflow/dags/scheduler.py
[2022-12-17 05:07:47,787] {processor.py:171} INFO - Processing /opt/airflow/dags/scheduler.py took 0.684 seconds
[2022-12-17 05:08:17,999] {processor.py:163} INFO - Started process (PID=188) to work on /opt/airflow/dags/scheduler.py
[2022-12-17 05:08:18,005] {processor.py:642} INFO - Processing file /opt/airflow/dags/scheduler.py for tasks to queue
[2022-12-17 05:08:18,008] {logging_mixin.py:109} INFO - [2022-12-17 05:08:18,008] {dagbag.py:500} INFO - Filling up the DagBag from /opt/airflow/dags/scheduler.py
[2022-12-17 05:08:18,252] {logging_mixin.py:109} INFO - [2022-12-17 05:08:18,244] {dagbag.py:334} ERROR - Failed to import: /opt/airflow/dags/scheduler.py
Traceback (most recent call last):
  File "/home/airflow/.local/lib/python3.7/site-packages/mysql/connector/connection_cext.py", line 236, in _open_connection
    self._cmysql.connect(**cnx_kwargs)
_mysql_connector.MySQLInterfaceError: Access denied for user 'airflow'@'172.24.0.7' (using password: NO)

During handling of the above exception, another exception occurred:

Traceback (most recent call last):
  File "/home/airflow/.local/lib/python3.7/site-packages/airflow/models/dagbag.py", line 331, in _load_modules_from_file
    loader.exec_module(new_module)
  File "<frozen importlib._bootstrap_external>", line 728, in exec_module
  File "<frozen importlib._bootstrap>", line 219, in _call_with_frames_removed
  File "/opt/airflow/dags/scheduler.py", line 17, in <module>
    connection = mysql.connector.connect(user=user, password=password, host=host, port=port, database=database, auth_plugin='mysql_native_password')
  File "/home/airflow/.local/lib/python3.7/site-packages/mysql/connector/__init__.py", line 272, in connect
    return CMySQLConnection(*args, **kwargs)
  File "/home/airflow/.local/lib/python3.7/site-packages/mysql/connector/connection_cext.py", line 85, in __init__
    self.connect(**kwargs)
  File "/home/airflow/.local/lib/python3.7/site-packages/mysql/connector/abstracts.py", line 1014, in connect
    self._open_connection()
  File "/home/airflow/.local/lib/python3.7/site-packages/mysql/connector/connection_cext.py", line 242, in _open_connection
    sqlstate=exc.sqlstate)
mysql.connector.errors.ProgrammingError: 1045 (28000): Access denied for user 'airflow'@'172.24.0.7' (using password: NO)
[2022-12-17 05:08:18,284] {processor.py:656} WARNING - No viable dags retrieved from /opt/airflow/dags/scheduler.py
[2022-12-17 05:08:18,308] {processor.py:171} INFO - Processing /opt/airflow/dags/scheduler.py took 0.320 seconds
[2022-12-17 05:08:48,675] {processor.py:163} INFO - Started process (PID=223) to work on /opt/airflow/dags/scheduler.py
[2022-12-17 05:08:48,679] {processor.py:642} INFO - Processing file /opt/airflow/dags/scheduler.py for tasks to queue
[2022-12-17 05:08:48,682] {logging_mixin.py:109} INFO - [2022-12-17 05:08:48,681] {dagbag.py:500} INFO - Filling up the DagBag from /opt/airflow/dags/scheduler.py
[2022-12-17 05:08:48,913] {logging_mixin.py:109} INFO - [2022-12-17 05:08:48,903] {dagbag.py:334} ERROR - Failed to import: /opt/airflow/dags/scheduler.py
Traceback (most recent call last):
  File "/home/airflow/.local/lib/python3.7/site-packages/mysql/connector/connection_cext.py", line 236, in _open_connection
    self._cmysql.connect(**cnx_kwargs)
_mysql_connector.MySQLInterfaceError: Access denied for user 'airflow'@'172.24.0.7' (using password: NO)

During handling of the above exception, another exception occurred:

Traceback (most recent call last):
  File "/home/airflow/.local/lib/python3.7/site-packages/airflow/models/dagbag.py", line 331, in _load_modules_from_file
    loader.exec_module(new_module)
  File "<frozen importlib._bootstrap_external>", line 728, in exec_module
  File "<frozen importlib._bootstrap>", line 219, in _call_with_frames_removed
  File "/opt/airflow/dags/scheduler.py", line 17, in <module>
    connection = mysql.connector.connect(user=user, password=password, host=host, port=port, database=database, auth_plugin='mysql_native_password')
  File "/home/airflow/.local/lib/python3.7/site-packages/mysql/connector/__init__.py", line 272, in connect
    return CMySQLConnection(*args, **kwargs)
  File "/home/airflow/.local/lib/python3.7/site-packages/mysql/connector/connection_cext.py", line 85, in __init__
    self.connect(**kwargs)
  File "/home/airflow/.local/lib/python3.7/site-packages/mysql/connector/abstracts.py", line 1014, in connect
    self._open_connection()
  File "/home/airflow/.local/lib/python3.7/site-packages/mysql/connector/connection_cext.py", line 242, in _open_connection
    sqlstate=exc.sqlstate)
mysql.connector.errors.ProgrammingError: 1045 (28000): Access denied for user 'airflow'@'172.24.0.7' (using password: NO)
[2022-12-17 05:08:48,972] {processor.py:656} WARNING - No viable dags retrieved from /opt/airflow/dags/scheduler.py
[2022-12-17 05:08:49,002] {processor.py:171} INFO - Processing /opt/airflow/dags/scheduler.py took 0.333 seconds
[2022-12-17 05:09:19,242] {processor.py:163} INFO - Started process (PID=252) to work on /opt/airflow/dags/scheduler.py
[2022-12-17 05:09:19,248] {processor.py:642} INFO - Processing file /opt/airflow/dags/scheduler.py for tasks to queue
[2022-12-17 05:09:19,251] {logging_mixin.py:109} INFO - [2022-12-17 05:09:19,250] {dagbag.py:500} INFO - Filling up the DagBag from /opt/airflow/dags/scheduler.py
[2022-12-17 05:09:19,498] {logging_mixin.py:109} INFO - [2022-12-17 05:09:19,489] {dagbag.py:334} ERROR - Failed to import: /opt/airflow/dags/scheduler.py
Traceback (most recent call last):
  File "/home/airflow/.local/lib/python3.7/site-packages/mysql/connector/connection_cext.py", line 236, in _open_connection
    self._cmysql.connect(**cnx_kwargs)
_mysql_connector.MySQLInterfaceError: Access denied for user 'airflow'@'172.24.0.7' (using password: NO)

During handling of the above exception, another exception occurred:

Traceback (most recent call last):
  File "/home/airflow/.local/lib/python3.7/site-packages/airflow/models/dagbag.py", line 331, in _load_modules_from_file
    loader.exec_module(new_module)
  File "<frozen importlib._bootstrap_external>", line 728, in exec_module
  File "<frozen importlib._bootstrap>", line 219, in _call_with_frames_removed
  File "/opt/airflow/dags/scheduler.py", line 17, in <module>
    connection = mysql.connector.connect(user=user, password=password, host=host, port=port, database=database, auth_plugin='mysql_native_password')
  File "/home/airflow/.local/lib/python3.7/site-packages/mysql/connector/__init__.py", line 272, in connect
    return CMySQLConnection(*args, **kwargs)
  File "/home/airflow/.local/lib/python3.7/site-packages/mysql/connector/connection_cext.py", line 85, in __init__
    self.connect(**kwargs)
  File "/home/airflow/.local/lib/python3.7/site-packages/mysql/connector/abstracts.py", line 1014, in connect
    self._open_connection()
  File "/home/airflow/.local/lib/python3.7/site-packages/mysql/connector/connection_cext.py", line 242, in _open_connection
    sqlstate=exc.sqlstate)
mysql.connector.errors.ProgrammingError: 1045 (28000): Access denied for user 'airflow'@'172.24.0.7' (using password: NO)
[2022-12-17 05:09:19,530] {processor.py:656} WARNING - No viable dags retrieved from /opt/airflow/dags/scheduler.py
[2022-12-17 05:09:19,555] {processor.py:171} INFO - Processing /opt/airflow/dags/scheduler.py took 0.335 seconds
[2022-12-17 05:09:49,742] {processor.py:163} INFO - Started process (PID=276) to work on /opt/airflow/dags/scheduler.py
[2022-12-17 05:09:49,745] {processor.py:642} INFO - Processing file /opt/airflow/dags/scheduler.py for tasks to queue
[2022-12-17 05:09:49,748] {logging_mixin.py:109} INFO - [2022-12-17 05:09:49,747] {dagbag.py:500} INFO - Filling up the DagBag from /opt/airflow/dags/scheduler.py
[2022-12-17 05:09:49,961] {logging_mixin.py:109} INFO - [2022-12-17 05:09:49,954] {dagbag.py:334} ERROR - Failed to import: /opt/airflow/dags/scheduler.py
Traceback (most recent call last):
  File "/home/airflow/.local/lib/python3.7/site-packages/mysql/connector/connection_cext.py", line 236, in _open_connection
    self._cmysql.connect(**cnx_kwargs)
_mysql_connector.MySQLInterfaceError: Access denied for user 'airflow'@'172.24.0.7' (using password: NO)

During handling of the above exception, another exception occurred:

Traceback (most recent call last):
  File "/home/airflow/.local/lib/python3.7/site-packages/airflow/models/dagbag.py", line 331, in _load_modules_from_file
    loader.exec_module(new_module)
  File "<frozen importlib._bootstrap_external>", line 728, in exec_module
  File "<frozen importlib._bootstrap>", line 219, in _call_with_frames_removed
  File "/opt/airflow/dags/scheduler.py", line 17, in <module>
    connection = mysql.connector.connect(user=user, password=password, host=host, port=port, database=database, auth_plugin='mysql_native_password')
  File "/home/airflow/.local/lib/python3.7/site-packages/mysql/connector/__init__.py", line 272, in connect
    return CMySQLConnection(*args, **kwargs)
  File "/home/airflow/.local/lib/python3.7/site-packages/mysql/connector/connection_cext.py", line 85, in __init__
    self.connect(**kwargs)
  File "/home/airflow/.local/lib/python3.7/site-packages/mysql/connector/abstracts.py", line 1014, in connect
    self._open_connection()
  File "/home/airflow/.local/lib/python3.7/site-packages/mysql/connector/connection_cext.py", line 242, in _open_connection
    sqlstate=exc.sqlstate)
mysql.connector.errors.ProgrammingError: 1045 (28000): Access denied for user 'airflow'@'172.24.0.7' (using password: NO)
[2022-12-17 05:09:49,990] {processor.py:656} WARNING - No viable dags retrieved from /opt/airflow/dags/scheduler.py
[2022-12-17 05:09:50,011] {processor.py:171} INFO - Processing /opt/airflow/dags/scheduler.py took 0.275 seconds
[2022-12-17 05:10:20,155] {processor.py:163} INFO - Started process (PID=310) to work on /opt/airflow/dags/scheduler.py
[2022-12-17 05:10:20,159] {processor.py:642} INFO - Processing file /opt/airflow/dags/scheduler.py for tasks to queue
[2022-12-17 05:10:20,162] {logging_mixin.py:109} INFO - [2022-12-17 05:10:20,161] {dagbag.py:500} INFO - Filling up the DagBag from /opt/airflow/dags/scheduler.py
[2022-12-17 05:10:20,368] {logging_mixin.py:109} INFO - [2022-12-17 05:10:20,358] {dagbag.py:334} ERROR - Failed to import: /opt/airflow/dags/scheduler.py
Traceback (most recent call last):
  File "/home/airflow/.local/lib/python3.7/site-packages/mysql/connector/connection_cext.py", line 236, in _open_connection
    self._cmysql.connect(**cnx_kwargs)
_mysql_connector.MySQLInterfaceError: Access denied for user 'airflow'@'172.24.0.7' (using password: NO)

During handling of the above exception, another exception occurred:

Traceback (most recent call last):
  File "/home/airflow/.local/lib/python3.7/site-packages/airflow/models/dagbag.py", line 331, in _load_modules_from_file
    loader.exec_module(new_module)
  File "<frozen importlib._bootstrap_external>", line 728, in exec_module
  File "<frozen importlib._bootstrap>", line 219, in _call_with_frames_removed
  File "/opt/airflow/dags/scheduler.py", line 17, in <module>
    connection = mysql.connector.connect(user=user, password=password, host=host, port=port, database=database, auth_plugin='mysql_native_password')
  File "/home/airflow/.local/lib/python3.7/site-packages/mysql/connector/__init__.py", line 272, in connect
    return CMySQLConnection(*args, **kwargs)
  File "/home/airflow/.local/lib/python3.7/site-packages/mysql/connector/connection_cext.py", line 85, in __init__
    self.connect(**kwargs)
  File "/home/airflow/.local/lib/python3.7/site-packages/mysql/connector/abstracts.py", line 1014, in connect
    self._open_connection()
  File "/home/airflow/.local/lib/python3.7/site-packages/mysql/connector/connection_cext.py", line 242, in _open_connection
    sqlstate=exc.sqlstate)
mysql.connector.errors.ProgrammingError: 1045 (28000): Access denied for user 'airflow'@'172.24.0.7' (using password: NO)
[2022-12-17 05:10:20,396] {processor.py:656} WARNING - No viable dags retrieved from /opt/airflow/dags/scheduler.py
[2022-12-17 05:10:20,419] {processor.py:171} INFO - Processing /opt/airflow/dags/scheduler.py took 0.281 seconds
[2022-12-17 05:10:50,568] {processor.py:163} INFO - Started process (PID=328) to work on /opt/airflow/dags/scheduler.py
[2022-12-17 05:10:50,572] {processor.py:642} INFO - Processing file /opt/airflow/dags/scheduler.py for tasks to queue
[2022-12-17 05:10:50,575] {logging_mixin.py:109} INFO - [2022-12-17 05:10:50,574] {dagbag.py:500} INFO - Filling up the DagBag from /opt/airflow/dags/scheduler.py
[2022-12-17 05:10:50,806] {logging_mixin.py:109} INFO - [2022-12-17 05:10:50,799] {dagbag.py:334} ERROR - Failed to import: /opt/airflow/dags/scheduler.py
Traceback (most recent call last):
  File "/home/airflow/.local/lib/python3.7/site-packages/mysql/connector/connection_cext.py", line 236, in _open_connection
    self._cmysql.connect(**cnx_kwargs)
_mysql_connector.MySQLInterfaceError: Access denied for user 'airflow'@'172.24.0.7' (using password: NO)

During handling of the above exception, another exception occurred:

Traceback (most recent call last):
  File "/home/airflow/.local/lib/python3.7/site-packages/airflow/models/dagbag.py", line 331, in _load_modules_from_file
    loader.exec_module(new_module)
  File "<frozen importlib._bootstrap_external>", line 728, in exec_module
  File "<frozen importlib._bootstrap>", line 219, in _call_with_frames_removed
  File "/opt/airflow/dags/scheduler.py", line 17, in <module>
    connection = mysql.connector.connect(user=user, password=password, host=host, port=port, database=database, auth_plugin='mysql_native_password')
  File "/home/airflow/.local/lib/python3.7/site-packages/mysql/connector/__init__.py", line 272, in connect
    return CMySQLConnection(*args, **kwargs)
  File "/home/airflow/.local/lib/python3.7/site-packages/mysql/connector/connection_cext.py", line 85, in __init__
    self.connect(**kwargs)
  File "/home/airflow/.local/lib/python3.7/site-packages/mysql/connector/abstracts.py", line 1014, in connect
    self._open_connection()
  File "/home/airflow/.local/lib/python3.7/site-packages/mysql/connector/connection_cext.py", line 242, in _open_connection
    sqlstate=exc.sqlstate)
mysql.connector.errors.ProgrammingError: 1045 (28000): Access denied for user 'airflow'@'172.24.0.7' (using password: NO)
[2022-12-17 05:10:50,839] {processor.py:656} WARNING - No viable dags retrieved from /opt/airflow/dags/scheduler.py
[2022-12-17 05:10:50,863] {processor.py:171} INFO - Processing /opt/airflow/dags/scheduler.py took 0.301 seconds
[2022-12-17 05:11:20,914] {processor.py:163} INFO - Started process (PID=362) to work on /opt/airflow/dags/scheduler.py
[2022-12-17 05:11:20,919] {processor.py:642} INFO - Processing file /opt/airflow/dags/scheduler.py for tasks to queue
[2022-12-17 05:11:20,921] {logging_mixin.py:109} INFO - [2022-12-17 05:11:20,921] {dagbag.py:500} INFO - Filling up the DagBag from /opt/airflow/dags/scheduler.py
[2022-12-17 05:11:21,154] {logging_mixin.py:109} INFO - [2022-12-17 05:11:21,145] {dagbag.py:334} ERROR - Failed to import: /opt/airflow/dags/scheduler.py
Traceback (most recent call last):
  File "/home/airflow/.local/lib/python3.7/site-packages/mysql/connector/connection_cext.py", line 236, in _open_connection
    self._cmysql.connect(**cnx_kwargs)
_mysql_connector.MySQLInterfaceError: Access denied for user 'airflow'@'172.24.0.7' (using password: NO)

During handling of the above exception, another exception occurred:

Traceback (most recent call last):
  File "/home/airflow/.local/lib/python3.7/site-packages/airflow/models/dagbag.py", line 331, in _load_modules_from_file
    loader.exec_module(new_module)
  File "<frozen importlib._bootstrap_external>", line 728, in exec_module
  File "<frozen importlib._bootstrap>", line 219, in _call_with_frames_removed
  File "/opt/airflow/dags/scheduler.py", line 17, in <module>
    connection = mysql.connector.connect(user=user, password=password, host=host, port=port, database=database, auth_plugin='mysql_native_password')
  File "/home/airflow/.local/lib/python3.7/site-packages/mysql/connector/__init__.py", line 272, in connect
    return CMySQLConnection(*args, **kwargs)
  File "/home/airflow/.local/lib/python3.7/site-packages/mysql/connector/connection_cext.py", line 85, in __init__
    self.connect(**kwargs)
  File "/home/airflow/.local/lib/python3.7/site-packages/mysql/connector/abstracts.py", line 1014, in connect
    self._open_connection()
  File "/home/airflow/.local/lib/python3.7/site-packages/mysql/connector/connection_cext.py", line 242, in _open_connection
    sqlstate=exc.sqlstate)
mysql.connector.errors.ProgrammingError: 1045 (28000): Access denied for user 'airflow'@'172.24.0.7' (using password: NO)
[2022-12-17 05:11:21,183] {processor.py:656} WARNING - No viable dags retrieved from /opt/airflow/dags/scheduler.py
[2022-12-17 05:11:21,203] {processor.py:171} INFO - Processing /opt/airflow/dags/scheduler.py took 0.297 seconds
[2022-12-17 05:21:04,336] {processor.py:163} INFO - Started process (PID=135) to work on /opt/airflow/dags/scheduler.py
[2022-12-17 05:21:04,349] {processor.py:642} INFO - Processing file /opt/airflow/dags/scheduler.py for tasks to queue
[2022-12-17 05:21:04,361] {logging_mixin.py:109} INFO - [2022-12-17 05:21:04,361] {dagbag.py:500} INFO - Filling up the DagBag from /opt/airflow/dags/scheduler.py
[2022-12-17 05:21:05,976] {logging_mixin.py:109} INFO - [2022-12-17 05:21:05,970] {dagbag.py:334} ERROR - Failed to import: /opt/airflow/dags/scheduler.py
Traceback (most recent call last):
  File "/home/airflow/.local/lib/python3.7/site-packages/airflow/models/dagbag.py", line 331, in _load_modules_from_file
    loader.exec_module(new_module)
  File "<frozen importlib._bootstrap_external>", line 728, in exec_module
  File "<frozen importlib._bootstrap>", line 219, in _call_with_frames_removed
  File "/opt/airflow/dags/scheduler.py", line 85, in <module>
    'new_employees': new_employees
  File "/home/airflow/.local/lib/python3.7/site-packages/airflow/models/baseoperator.py", line 177, in apply_defaults
    raise AirflowException(msg)
airflow.exceptions.AirflowException: Argument ['python_callable'] is required
[2022-12-17 05:21:06,006] {processor.py:656} WARNING - No viable dags retrieved from /opt/airflow/dags/scheduler.py
[2022-12-17 05:21:06,029] {processor.py:171} INFO - Processing /opt/airflow/dags/scheduler.py took 1.720 seconds
[2022-12-17 05:21:36,201] {processor.py:163} INFO - Started process (PID=171) to work on /opt/airflow/dags/scheduler.py
[2022-12-17 05:21:36,209] {processor.py:642} INFO - Processing file /opt/airflow/dags/scheduler.py for tasks to queue
[2022-12-17 05:21:36,213] {logging_mixin.py:109} INFO - [2022-12-17 05:21:36,211] {dagbag.py:500} INFO - Filling up the DagBag from /opt/airflow/dags/scheduler.py
[2022-12-17 05:21:36,846] {logging_mixin.py:109} INFO - [2022-12-17 05:21:36,832] {dagbag.py:334} ERROR - Failed to import: /opt/airflow/dags/scheduler.py
Traceback (most recent call last):
  File "/home/airflow/.local/lib/python3.7/site-packages/airflow/models/dagbag.py", line 331, in _load_modules_from_file
    loader.exec_module(new_module)
  File "<frozen importlib._bootstrap_external>", line 728, in exec_module
  File "<frozen importlib._bootstrap>", line 219, in _call_with_frames_removed
  File "/opt/airflow/dags/scheduler.py", line 85, in <module>
    'new_employees': new_employees
  File "/home/airflow/.local/lib/python3.7/site-packages/airflow/models/baseoperator.py", line 177, in apply_defaults
    raise AirflowException(msg)
airflow.exceptions.AirflowException: Argument ['python_callable'] is required
[2022-12-17 05:21:36,905] {processor.py:656} WARNING - No viable dags retrieved from /opt/airflow/dags/scheduler.py
[2022-12-17 05:21:36,954] {processor.py:171} INFO - Processing /opt/airflow/dags/scheduler.py took 0.769 seconds
[2022-12-17 05:22:07,263] {processor.py:163} INFO - Started process (PID=189) to work on /opt/airflow/dags/scheduler.py
[2022-12-17 05:22:07,266] {processor.py:642} INFO - Processing file /opt/airflow/dags/scheduler.py for tasks to queue
[2022-12-17 05:22:07,268] {logging_mixin.py:109} INFO - [2022-12-17 05:22:07,268] {dagbag.py:500} INFO - Filling up the DagBag from /opt/airflow/dags/scheduler.py
[2022-12-17 05:22:07,480] {logging_mixin.py:109} INFO - [2022-12-17 05:22:07,475] {dagbag.py:334} ERROR - Failed to import: /opt/airflow/dags/scheduler.py
Traceback (most recent call last):
  File "/home/airflow/.local/lib/python3.7/site-packages/airflow/models/dagbag.py", line 331, in _load_modules_from_file
    loader.exec_module(new_module)
  File "<frozen importlib._bootstrap_external>", line 728, in exec_module
  File "<frozen importlib._bootstrap>", line 219, in _call_with_frames_removed
  File "/opt/airflow/dags/scheduler.py", line 85, in <module>
    'new_employees': new_employees
  File "/home/airflow/.local/lib/python3.7/site-packages/airflow/models/baseoperator.py", line 177, in apply_defaults
    raise AirflowException(msg)
airflow.exceptions.AirflowException: Argument ['python_callable'] is required
[2022-12-17 05:22:07,507] {processor.py:656} WARNING - No viable dags retrieved from /opt/airflow/dags/scheduler.py
[2022-12-17 05:22:07,526] {processor.py:171} INFO - Processing /opt/airflow/dags/scheduler.py took 0.270 seconds
[2022-12-17 05:22:37,612] {processor.py:163} INFO - Started process (PID=223) to work on /opt/airflow/dags/scheduler.py
[2022-12-17 05:22:37,617] {processor.py:642} INFO - Processing file /opt/airflow/dags/scheduler.py for tasks to queue
[2022-12-17 05:22:37,619] {logging_mixin.py:109} INFO - [2022-12-17 05:22:37,619] {dagbag.py:500} INFO - Filling up the DagBag from /opt/airflow/dags/scheduler.py
[2022-12-17 05:22:37,932] {logging_mixin.py:109} INFO - [2022-12-17 05:22:37,926] {dagbag.py:334} ERROR - Failed to import: /opt/airflow/dags/scheduler.py
Traceback (most recent call last):
  File "/home/airflow/.local/lib/python3.7/site-packages/airflow/models/dagbag.py", line 331, in _load_modules_from_file
    loader.exec_module(new_module)
  File "<frozen importlib._bootstrap_external>", line 728, in exec_module
  File "<frozen importlib._bootstrap>", line 219, in _call_with_frames_removed
  File "/opt/airflow/dags/scheduler.py", line 85, in <module>
    'new_employees': new_employees
  File "/home/airflow/.local/lib/python3.7/site-packages/airflow/models/baseoperator.py", line 177, in apply_defaults
    raise AirflowException(msg)
airflow.exceptions.AirflowException: Argument ['python_callable'] is required
[2022-12-17 05:22:37,962] {processor.py:656} WARNING - No viable dags retrieved from /opt/airflow/dags/scheduler.py
[2022-12-17 05:22:37,990] {processor.py:171} INFO - Processing /opt/airflow/dags/scheduler.py took 0.384 seconds
[2022-12-17 05:23:08,174] {processor.py:163} INFO - Started process (PID=240) to work on /opt/airflow/dags/scheduler.py
[2022-12-17 05:23:08,178] {processor.py:642} INFO - Processing file /opt/airflow/dags/scheduler.py for tasks to queue
[2022-12-17 05:23:08,181] {logging_mixin.py:109} INFO - [2022-12-17 05:23:08,180] {dagbag.py:500} INFO - Filling up the DagBag from /opt/airflow/dags/scheduler.py
[2022-12-17 05:23:08,389] {logging_mixin.py:109} INFO - [2022-12-17 05:23:08,383] {dagbag.py:334} ERROR - Failed to import: /opt/airflow/dags/scheduler.py
Traceback (most recent call last):
  File "/home/airflow/.local/lib/python3.7/site-packages/airflow/models/dagbag.py", line 331, in _load_modules_from_file
    loader.exec_module(new_module)
  File "<frozen importlib._bootstrap_external>", line 728, in exec_module
  File "<frozen importlib._bootstrap>", line 219, in _call_with_frames_removed
  File "/opt/airflow/dags/scheduler.py", line 85, in <module>
    'new_employees': new_employees
  File "/home/airflow/.local/lib/python3.7/site-packages/airflow/models/baseoperator.py", line 177, in apply_defaults
    raise AirflowException(msg)
airflow.exceptions.AirflowException: Argument ['python_callable'] is required
[2022-12-17 05:23:08,415] {processor.py:656} WARNING - No viable dags retrieved from /opt/airflow/dags/scheduler.py
[2022-12-17 05:23:08,435] {processor.py:171} INFO - Processing /opt/airflow/dags/scheduler.py took 0.268 seconds
[2022-12-17 05:23:38,540] {processor.py:163} INFO - Started process (PID=275) to work on /opt/airflow/dags/scheduler.py
[2022-12-17 05:23:38,545] {processor.py:642} INFO - Processing file /opt/airflow/dags/scheduler.py for tasks to queue
[2022-12-17 05:23:38,547] {logging_mixin.py:109} INFO - [2022-12-17 05:23:38,547] {dagbag.py:500} INFO - Filling up the DagBag from /opt/airflow/dags/scheduler.py
[2022-12-17 05:23:38,849] {logging_mixin.py:109} INFO - [2022-12-17 05:23:38,841] {dagbag.py:334} ERROR - Failed to import: /opt/airflow/dags/scheduler.py
Traceback (most recent call last):
  File "/home/airflow/.local/lib/python3.7/site-packages/airflow/models/dagbag.py", line 331, in _load_modules_from_file
    loader.exec_module(new_module)
  File "<frozen importlib._bootstrap_external>", line 728, in exec_module
  File "<frozen importlib._bootstrap>", line 219, in _call_with_frames_removed
  File "/opt/airflow/dags/scheduler.py", line 85, in <module>
    'new_employees': new_employees
  File "/home/airflow/.local/lib/python3.7/site-packages/airflow/models/baseoperator.py", line 177, in apply_defaults
    raise AirflowException(msg)
airflow.exceptions.AirflowException: Argument ['python_callable'] is required
[2022-12-17 05:23:38,881] {processor.py:656} WARNING - No viable dags retrieved from /opt/airflow/dags/scheduler.py
[2022-12-17 05:23:38,903] {processor.py:171} INFO - Processing /opt/airflow/dags/scheduler.py took 0.377 seconds
[2022-12-17 05:24:09,102] {processor.py:163} INFO - Started process (PID=293) to work on /opt/airflow/dags/scheduler.py
[2022-12-17 05:24:09,105] {processor.py:642} INFO - Processing file /opt/airflow/dags/scheduler.py for tasks to queue
[2022-12-17 05:24:09,108] {logging_mixin.py:109} INFO - [2022-12-17 05:24:09,108] {dagbag.py:500} INFO - Filling up the DagBag from /opt/airflow/dags/scheduler.py
[2022-12-17 05:24:09,355] {logging_mixin.py:109} INFO - [2022-12-17 05:24:09,350] {dagbag.py:334} ERROR - Failed to import: /opt/airflow/dags/scheduler.py
Traceback (most recent call last):
  File "/home/airflow/.local/lib/python3.7/site-packages/airflow/models/dagbag.py", line 331, in _load_modules_from_file
    loader.exec_module(new_module)
  File "<frozen importlib._bootstrap_external>", line 728, in exec_module
  File "<frozen importlib._bootstrap>", line 219, in _call_with_frames_removed
  File "/opt/airflow/dags/scheduler.py", line 85, in <module>
    'new_employees': new_employees
  File "/home/airflow/.local/lib/python3.7/site-packages/airflow/models/baseoperator.py", line 177, in apply_defaults
    raise AirflowException(msg)
airflow.exceptions.AirflowException: Argument ['python_callable'] is required
[2022-12-17 05:24:09,384] {processor.py:656} WARNING - No viable dags retrieved from /opt/airflow/dags/scheduler.py
[2022-12-17 05:24:09,405] {processor.py:171} INFO - Processing /opt/airflow/dags/scheduler.py took 0.310 seconds
[2022-12-17 05:24:39,570] {processor.py:163} INFO - Started process (PID=327) to work on /opt/airflow/dags/scheduler.py
[2022-12-17 05:24:39,579] {processor.py:642} INFO - Processing file /opt/airflow/dags/scheduler.py for tasks to queue
[2022-12-17 05:24:39,582] {logging_mixin.py:109} INFO - [2022-12-17 05:24:39,581] {dagbag.py:500} INFO - Filling up the DagBag from /opt/airflow/dags/scheduler.py
[2022-12-17 05:24:39,845] {logging_mixin.py:109} INFO - [2022-12-17 05:24:39,839] {dagbag.py:334} ERROR - Failed to import: /opt/airflow/dags/scheduler.py
Traceback (most recent call last):
  File "/home/airflow/.local/lib/python3.7/site-packages/airflow/models/dagbag.py", line 331, in _load_modules_from_file
    loader.exec_module(new_module)
  File "<frozen importlib._bootstrap_external>", line 728, in exec_module
  File "<frozen importlib._bootstrap>", line 219, in _call_with_frames_removed
  File "/opt/airflow/dags/scheduler.py", line 85, in <module>
    'new_employees': new_employees
  File "/home/airflow/.local/lib/python3.7/site-packages/airflow/models/baseoperator.py", line 177, in apply_defaults
    raise AirflowException(msg)
airflow.exceptions.AirflowException: Argument ['python_callable'] is required
[2022-12-17 05:24:39,874] {processor.py:656} WARNING - No viable dags retrieved from /opt/airflow/dags/scheduler.py
[2022-12-17 05:24:39,898] {processor.py:171} INFO - Processing /opt/airflow/dags/scheduler.py took 0.334 seconds
[2022-12-17 05:24:54,681] {processor.py:163} INFO - Started process (PID=345) to work on /opt/airflow/dags/scheduler.py
[2022-12-17 05:24:54,684] {processor.py:642} INFO - Processing file /opt/airflow/dags/scheduler.py for tasks to queue
[2022-12-17 05:24:54,686] {logging_mixin.py:109} INFO - [2022-12-17 05:24:54,686] {dagbag.py:500} INFO - Filling up the DagBag from /opt/airflow/dags/scheduler.py
[2022-12-17 05:24:55,018] {processor.py:654} INFO - DAG(s) dict_keys(['scheduler_dag']) retrieved from /opt/airflow/dags/scheduler.py
[2022-12-17 05:30:40,656] {processor.py:163} INFO - Started process (PID=135) to work on /opt/airflow/dags/scheduler.py
[2022-12-17 05:30:40,681] {processor.py:642} INFO - Processing file /opt/airflow/dags/scheduler.py for tasks to queue
[2022-12-17 05:30:40,683] {logging_mixin.py:109} INFO - [2022-12-17 05:30:40,683] {dagbag.py:500} INFO - Filling up the DagBag from /opt/airflow/dags/scheduler.py
[2022-12-17 05:30:42,359] {processor.py:654} INFO - DAG(s) dict_keys(['scheduler_dag']) retrieved from /opt/airflow/dags/scheduler.py
[2022-12-17 05:31:23,936] {logging_mixin.py:109} INFO - [2022-12-17 05:31:23,936] {manager.py:496} INFO - Created Permission View: can read on DAG:scheduler_dag
[2022-12-17 05:31:23,975] {logging_mixin.py:109} INFO - [2022-12-17 05:31:23,975] {manager.py:496} INFO - Created Permission View: can edit on DAG:scheduler_dag
[2022-12-17 05:31:23,977] {logging_mixin.py:109} INFO - [2022-12-17 05:31:23,976] {dag.py:2396} INFO - Sync 1 DAGs
[2022-12-17 05:31:24,018] {logging_mixin.py:109} INFO - [2022-12-17 05:31:24,014] {dag.py:2415} INFO - Creating ORM DAG for scheduler_dag
[2022-12-17 05:31:24,080] {logging_mixin.py:109} INFO - [2022-12-17 05:31:24,080] {dag.py:2935} INFO - Setting next_dagrun for scheduler_dag to 2022-12-04 00:00:00+00:00
[2022-12-17 05:31:24,148] {processor.py:171} INFO - Processing /opt/airflow/dags/scheduler.py took 43.501 seconds
[2022-12-17 05:31:54,442] {processor.py:163} INFO - Started process (PID=203) to work on /opt/airflow/dags/scheduler.py
[2022-12-17 05:31:54,446] {processor.py:642} INFO - Processing file /opt/airflow/dags/scheduler.py for tasks to queue
[2022-12-17 05:31:54,448] {logging_mixin.py:109} INFO - [2022-12-17 05:31:54,448] {dagbag.py:500} INFO - Filling up the DagBag from /opt/airflow/dags/scheduler.py
[2022-12-17 05:31:54,732] {processor.py:654} INFO - DAG(s) dict_keys(['scheduler_dag']) retrieved from /opt/airflow/dags/scheduler.py
[2022-12-17 05:31:54,761] {logging_mixin.py:109} INFO - [2022-12-17 05:31:54,760] {dag.py:2396} INFO - Sync 1 DAGs
[2022-12-17 05:31:54,818] {logging_mixin.py:109} INFO - [2022-12-17 05:31:54,818] {dag.py:2935} INFO - Setting next_dagrun for scheduler_dag to 2022-12-04 00:00:00+00:00
[2022-12-17 05:31:54,840] {processor.py:171} INFO - Processing /opt/airflow/dags/scheduler.py took 0.405 seconds
[2022-12-17 05:32:25,034] {processor.py:163} INFO - Started process (PID=221) to work on /opt/airflow/dags/scheduler.py
[2022-12-17 05:32:25,039] {processor.py:642} INFO - Processing file /opt/airflow/dags/scheduler.py for tasks to queue
[2022-12-17 05:32:25,042] {logging_mixin.py:109} INFO - [2022-12-17 05:32:25,041] {dagbag.py:500} INFO - Filling up the DagBag from /opt/airflow/dags/scheduler.py
[2022-12-17 05:32:25,308] {processor.py:654} INFO - DAG(s) dict_keys(['scheduler_dag']) retrieved from /opt/airflow/dags/scheduler.py
[2022-12-17 05:32:25,338] {logging_mixin.py:109} INFO - [2022-12-17 05:32:25,338] {dag.py:2396} INFO - Sync 1 DAGs
[2022-12-17 05:32:25,395] {logging_mixin.py:109} INFO - [2022-12-17 05:32:25,394] {dag.py:2935} INFO - Setting next_dagrun for scheduler_dag to 2022-12-11T00:00:00+00:00
[2022-12-17 05:32:25,418] {processor.py:171} INFO - Processing /opt/airflow/dags/scheduler.py took 0.390 seconds
[2022-12-17 05:32:55,600] {processor.py:163} INFO - Started process (PID=256) to work on /opt/airflow/dags/scheduler.py
[2022-12-17 05:32:55,605] {processor.py:642} INFO - Processing file /opt/airflow/dags/scheduler.py for tasks to queue
[2022-12-17 05:32:55,607] {logging_mixin.py:109} INFO - [2022-12-17 05:32:55,607] {dagbag.py:500} INFO - Filling up the DagBag from /opt/airflow/dags/scheduler.py
[2022-12-17 05:32:56,018] {processor.py:654} INFO - DAG(s) dict_keys(['scheduler_dag']) retrieved from /opt/airflow/dags/scheduler.py
[2022-12-17 05:32:56,076] {logging_mixin.py:109} INFO - [2022-12-17 05:32:56,076] {dag.py:2396} INFO - Sync 1 DAGs
[2022-12-17 05:32:56,133] {logging_mixin.py:109} INFO - [2022-12-17 05:32:56,133] {dag.py:2935} INFO - Setting next_dagrun for scheduler_dag to 2022-12-11T00:00:00+00:00
[2022-12-17 05:32:56,163] {processor.py:171} INFO - Processing /opt/airflow/dags/scheduler.py took 0.569 seconds
[2022-12-17 05:33:26,405] {processor.py:163} INFO - Started process (PID=274) to work on /opt/airflow/dags/scheduler.py
[2022-12-17 05:33:26,409] {processor.py:642} INFO - Processing file /opt/airflow/dags/scheduler.py for tasks to queue
[2022-12-17 05:33:26,411] {logging_mixin.py:109} INFO - [2022-12-17 05:33:26,410] {dagbag.py:500} INFO - Filling up the DagBag from /opt/airflow/dags/scheduler.py
[2022-12-17 05:33:26,647] {processor.py:654} INFO - DAG(s) dict_keys(['scheduler_dag']) retrieved from /opt/airflow/dags/scheduler.py
[2022-12-17 05:33:26,675] {logging_mixin.py:109} INFO - [2022-12-17 05:33:26,674] {dag.py:2396} INFO - Sync 1 DAGs
[2022-12-17 05:33:26,734] {logging_mixin.py:109} INFO - [2022-12-17 05:33:26,733] {dag.py:2935} INFO - Setting next_dagrun for scheduler_dag to 2022-12-11T00:00:00+00:00
[2022-12-17 05:33:26,755] {processor.py:171} INFO - Processing /opt/airflow/dags/scheduler.py took 0.357 seconds
[2022-12-17 05:33:51,939] {processor.py:163} INFO - Started process (PID=308) to work on /opt/airflow/dags/scheduler.py
[2022-12-17 05:33:51,947] {processor.py:642} INFO - Processing file /opt/airflow/dags/scheduler.py for tasks to queue
[2022-12-17 05:33:51,952] {logging_mixin.py:109} INFO - [2022-12-17 05:33:51,952] {dagbag.py:500} INFO - Filling up the DagBag from /opt/airflow/dags/scheduler.py
[2022-12-17 05:33:52,302] {processor.py:654} INFO - DAG(s) dict_keys(['scheduler_dag']) retrieved from /opt/airflow/dags/scheduler.py
[2022-12-17 05:33:52,355] {logging_mixin.py:109} INFO - [2022-12-17 05:33:52,354] {dag.py:2396} INFO - Sync 1 DAGs
[2022-12-17 05:33:52,428] {logging_mixin.py:109} INFO - [2022-12-17 05:33:52,427] {dag.py:2935} INFO - Setting next_dagrun for scheduler_dag to 2022-12-11T00:00:00+00:00
[2022-12-17 05:33:52,474] {processor.py:171} INFO - Processing /opt/airflow/dags/scheduler.py took 0.552 seconds
[2022-12-17 05:33:52,920] {processor.py:163} INFO - Started process (PID=310) to work on /opt/airflow/dags/scheduler.py
[2022-12-17 05:33:52,923] {processor.py:642} INFO - Processing file /opt/airflow/dags/scheduler.py for tasks to queue
[2022-12-17 05:33:52,925] {logging_mixin.py:109} INFO - [2022-12-17 05:33:52,925] {dagbag.py:500} INFO - Filling up the DagBag from /opt/airflow/dags/scheduler.py
[2022-12-17 05:33:53,199] {processor.py:654} INFO - DAG(s) dict_keys(['scheduler_dag']) retrieved from /opt/airflow/dags/scheduler.py
[2022-12-17 05:33:53,228] {logging_mixin.py:109} INFO - [2022-12-17 05:33:53,228] {dag.py:2396} INFO - Sync 1 DAGs
[2022-12-17 05:33:53,284] {logging_mixin.py:109} INFO - [2022-12-17 05:33:53,284] {dag.py:2935} INFO - Setting next_dagrun for scheduler_dag to 2022-12-11T00:00:00+00:00
[2022-12-17 05:33:53,311] {processor.py:171} INFO - Processing /opt/airflow/dags/scheduler.py took 0.397 seconds
[2022-12-17 05:34:23,511] {processor.py:163} INFO - Started process (PID=327) to work on /opt/airflow/dags/scheduler.py
[2022-12-17 05:34:23,515] {processor.py:642} INFO - Processing file /opt/airflow/dags/scheduler.py for tasks to queue
[2022-12-17 05:34:23,517] {logging_mixin.py:109} INFO - [2022-12-17 05:34:23,517] {dagbag.py:500} INFO - Filling up the DagBag from /opt/airflow/dags/scheduler.py
[2022-12-17 05:34:23,764] {processor.py:654} INFO - DAG(s) dict_keys(['scheduler_dag']) retrieved from /opt/airflow/dags/scheduler.py
[2022-12-17 05:34:23,792] {logging_mixin.py:109} INFO - [2022-12-17 05:34:23,792] {dag.py:2396} INFO - Sync 1 DAGs
[2022-12-17 05:34:23,848] {logging_mixin.py:109} INFO - [2022-12-17 05:34:23,847] {dag.py:2935} INFO - Setting next_dagrun for scheduler_dag to 2022-12-11T00:00:00+00:00
[2022-12-17 05:34:23,871] {processor.py:171} INFO - Processing /opt/airflow/dags/scheduler.py took 0.366 seconds
[2022-12-17 05:34:27,588] {processor.py:163} INFO - Started process (PID=336) to work on /opt/airflow/dags/scheduler.py
[2022-12-17 05:34:27,593] {processor.py:642} INFO - Processing file /opt/airflow/dags/scheduler.py for tasks to queue
[2022-12-17 05:34:27,596] {logging_mixin.py:109} INFO - [2022-12-17 05:34:27,596] {dagbag.py:500} INFO - Filling up the DagBag from /opt/airflow/dags/scheduler.py
[2022-12-17 05:34:27,879] {processor.py:654} INFO - DAG(s) dict_keys(['scheduler_dag']) retrieved from /opt/airflow/dags/scheduler.py
[2022-12-17 05:34:27,909] {logging_mixin.py:109} INFO - [2022-12-17 05:34:27,909] {dag.py:2396} INFO - Sync 1 DAGs
[2022-12-17 05:34:27,974] {logging_mixin.py:109} INFO - [2022-12-17 05:34:27,974] {dag.py:2935} INFO - Setting next_dagrun for scheduler_dag to 2022-12-11T00:00:00+00:00
[2022-12-17 05:34:28,009] {processor.py:171} INFO - Processing /opt/airflow/dags/scheduler.py took 0.428 seconds
[2022-12-17 05:34:58,209] {processor.py:163} INFO - Started process (PID=363) to work on /opt/airflow/dags/scheduler.py
[2022-12-17 05:34:58,216] {processor.py:642} INFO - Processing file /opt/airflow/dags/scheduler.py for tasks to queue
[2022-12-17 05:34:58,218] {logging_mixin.py:109} INFO - [2022-12-17 05:34:58,218] {dagbag.py:500} INFO - Filling up the DagBag from /opt/airflow/dags/scheduler.py
[2022-12-17 05:34:58,495] {logging_mixin.py:109} INFO - [2022-12-17 05:34:58,486] {dagbag.py:334} ERROR - Failed to import: /opt/airflow/dags/scheduler.py
Traceback (most recent call last):
  File "/home/airflow/.local/lib/python3.7/site-packages/mysql/connector/connection_cext.py", line 236, in _open_connection
    self._cmysql.connect(**cnx_kwargs)
_mysql_connector.MySQLInterfaceError: Unknown MySQL server host 'warehouse' (-2)

During handling of the above exception, another exception occurred:

Traceback (most recent call last):
  File "/home/airflow/.local/lib/python3.7/site-packages/airflow/models/dagbag.py", line 331, in _load_modules_from_file
    loader.exec_module(new_module)
  File "<frozen importlib._bootstrap_external>", line 728, in exec_module
  File "<frozen importlib._bootstrap>", line 219, in _call_with_frames_removed
  File "/opt/airflow/dags/scheduler.py", line 17, in <module>
    connection = mysql.connector.connect(user=user, password=password, host=host, port=port, database=database, auth_plugin='mysql_native_password')
  File "/home/airflow/.local/lib/python3.7/site-packages/mysql/connector/__init__.py", line 272, in connect
    return CMySQLConnection(*args, **kwargs)
  File "/home/airflow/.local/lib/python3.7/site-packages/mysql/connector/connection_cext.py", line 85, in __init__
    self.connect(**kwargs)
  File "/home/airflow/.local/lib/python3.7/site-packages/mysql/connector/abstracts.py", line 1014, in connect
    self._open_connection()
  File "/home/airflow/.local/lib/python3.7/site-packages/mysql/connector/connection_cext.py", line 242, in _open_connection
    sqlstate=exc.sqlstate)
mysql.connector.errors.DatabaseError: 2005 (HY000): Unknown MySQL server host 'warehouse' (-2)
[2022-12-17 05:34:58,522] {processor.py:690} INFO - Deactivated 1 DAGs which are no longer present in /opt/airflow/dags/scheduler.py
[2022-12-17 05:34:58,523] {processor.py:656} WARNING - No viable dags retrieved from /opt/airflow/dags/scheduler.py
[2022-12-17 05:34:58,543] {processor.py:171} INFO - Processing /opt/airflow/dags/scheduler.py took 0.339 seconds
